Workbook
Name Slicer_ارز: #N/A
Name Slicer_کد_پروژه: #N/A

Sheet نقدینگی ارزی
C12: ارز | D12: تولید | E12: تامین | F12: نصب | G12: راه‌اندازی | H12: مکانیکال | I12: مهندسی | J12: مدیریت | K12: مجموع
B13: جمع | C13: $ | D13: =SUMPRODUCT(SUBTOTAL(9, OFFSET(D19,ROW(Table2[تولید])-ROW(D19), 0)), --(Table2[ارز]=C13)) -> 0 | E13: =SUMPRODUCT(SUBTOTAL(9, OFFSET(E19,ROW(Table2[تامین])-ROW(E19), 0)), --(Table2[ارز]=C13)) -> 0 | F13: =SUMPRODUCT(SUBTOTAL(9, OFFSET(F19,ROW(Table2[نصب])-ROW(F19), 0)), --(Table2[ارز]=C13)) -> 0 | G13: =SUMPRODUCT(SUBTOTAL(9, OFFSET(G19,ROW(Table2[راه اندازی])-ROW(G19), 0)), --(Table2[ارز]=C13)) -> 0 | H13: =SUMPRODUCT(SUBTOTAL(9, OFFSET(H19,ROW(Table2[مکانیکال])-ROW(H19), 0)), --(Table2[ارز]=C13)) -> 0 | I13: =SUMPRODUCT(SUBTOTAL(9, OFFSET(I19,ROW(Table2[مهندسی])-ROW(I19), 0)), --(Table2[ارز]=C13)) -> 0 | J13: =SUMPRODUCT(SUBTOTAL(9, OFFSET(J19,ROW(Table2[مدیریت])-ROW(J19), 0)), --(Table2[ارز]=C13)) -> 0 | K13: =SUMPRODUCT(SUBTOTAL(9, OFFSET(K19,ROW(Table2[جمع])-ROW(K19), 0)), --(Table2[ارز]=C13)) -> 0
B14: جمع | C14: ¥ | D14: =SUMPRODUCT(SUBTOTAL(9, OFFSET(D19,ROW(Table2[تولید])-ROW(D19), 0)), --(Table2[ارز]=C14)) -> 0 | E14: =SUMPRODUCT(SUBTOTAL(9, OFFSET(E19,ROW(Table2[تامین])-ROW(E19), 0)), --(Table2[ارز]=C14)) -> 0 | F14: =SUMPRODUCT(SUBTOTAL(9, OFFSET(F19,ROW(Table2[نصب])-ROW(F19), 0)), --(Table2[ارز]=C14)) -> 0 | G14: =SUMPRODUCT(SUBTOTAL(9, OFFSET(G19,ROW(Table2[راه اندازی])-ROW(G19), 0)), --(Table2[ارز]=C14)) -> 0 | H14: =SUMPRODUCT(SUBTOTAL(9, OFFSET(H19,ROW(Table2[مکانیکال])-ROW(H19), 0)), --(Table2[ارز]=C14)) -> 0 | I14: =SUMPRODUCT(SUBTOTAL(9, OFFSET(I19,ROW(Table2[مهندسی])-ROW(I19), 0)), --(Table2[ارز]=C14)) -> 0 | J14: =SUMPRODUCT(SUBTOTAL(9, OFFSET(J19,ROW(Table2[مدیریت])-ROW(J19), 0)), --(Table2[ارز]=C14)) -> 0 | K14: =SUMPRODUCT(SUBTOTAL(9, OFFSET(K19,ROW(Table2[جمع])-ROW(K19), 0)), --(Table2[ارز]=C14)) -> 0
B15: جمع | C15: € | D15: =SUMPRODUCT(SUBTOTAL(9, OFFSET(D19,ROW(Table2[تولید])-ROW(D19), 0)), --(Table2[ارز]=C15)) -> 0 | E15: =SUMPRODUCT(SUBTOTAL(9, OFFSET(E19,ROW(Table2[تامین])-ROW(E19), 0)), --(Table2[ارز]=C15)) -> 0 | F15: =SUMPRODUCT(SUBTOTAL(9, OFFSET(F19,ROW(Table2[نصب])-ROW(F19), 0)), --(Table2[ارز]=C15)) -> 0 | G15: =SUMPRODUCT(SUBTOTAL(9, OFFSET(G19,ROW(Table2[راه اندازی])-ROW(G19), 0)), --(Table2[ارز]=C15)) -> 0 | H15: =SUMPRODUCT(SUBTOTAL(9, OFFSET(H19,ROW(Table2[مکانیکال])-ROW(H19), 0)), --(Table2[ارز]=C15)) -> 0 | I15: =SUMPRODUCT(SUBTOTAL(9, OFFSET(I19,ROW(Table2[مهندسی])-ROW(I19), 0)), --(Table2[ارز]=C15)) -> 0 | J15: =SUMPRODUCT(SUBTOTAL(9, OFFSET(J19,ROW(Table2[مدیریت])-ROW(J19), 0)), --(Table2[ارز]=C15)) -> 0 | K15: =SUMPRODUCT(SUBTOTAL(9, OFFSET(K19,ROW(Table2[جمع])-ROW(K19), 0)), --(Table2[ارز]=C15)) -> 0
B16: جمع | C16: AED | D16: =SUMPRODUCT(SUBTOTAL(9, OFFSET(D19,ROW(Table2[تولید])-ROW(D19), 0)), --(Table2[ارز]=C16)) -> 8.1034483 | E16: =SUMPRODUCT(SUBTOTAL(9, OFFSET(E19,ROW(Table2[تامین])-ROW(E19), 0)), --(Table2[ارز]=C16)) -> 447.7 | F16: =SUMPRODUCT(SUBTOTAL(9, OFFSET(F19,ROW(Table2[نصب])-ROW(F19), 0)), --(Table2[ارز]=C16)) -> 0 | G16: =SUMPRODUCT(SUBTOTAL(9, OFFSET(G19,ROW(Table2[راه اندازی])-ROW(G19), 0)), --(Table2[ارز]=C16)) -> 0 | H16: =SUMPRODUCT(SUBTOTAL(9, OFFSET(H19,ROW(Table2[مکانیکال])-ROW(H19), 0)), --(Table2[ارز]=C16)) -> 191.2 | I16: =SUMPRODUCT(SUBTOTAL(9, OFFSET(I19,ROW(Table2[مهندسی])-ROW(I19), 0)), --(Table2[ارز]=C16)) -> 305.2 | J16: =SUMPRODUCT(SUBTOTAL(9, OFFSET(J19,ROW(Table2[مدیریت])-ROW(J19), 0)), --(Table2[ارز]=C16)) -> 0 | K16: =SUMPRODUCT(SUBTOTAL(9, OFFSET(K19,ROW(Table2[جمع])-ROW(K19), 0)), --(Table2[ارز]=C16)) -> 1209.2034
B18: کد پروژه | C18: ارز | D18: تولید | E18: تامین | F18: نصب | G18: راه اندازی | H18: مکانیکال | I18: مهندسی | J18: مدیریت | K18: جمع
B19: Project 1 | C19: $ | D19: =SUMIFS('ریز نقدینگی ارزی'!$F$4:$F$1036,'ریز نقدینگی ارزی'!$F$4:$F$1036,">0",'ریز نقدینگی ارزی'!$C$4:$C$1036,B19,'ریز نقدینگی ارزی'!$E$4:$E$1036,$D$18,'ریز نقدینگی ارزی'!$B$4:$B$1036,C19)-SUMIFS('ریز نقدینگی ارزی'!$G$4:$G$1036,'ریز نقدینگی ارزی'!$G$4:$G$1036,">0",'ریز نقدینگی ارزی'!$C$4:$C$1036,B19,'ریز نقدینگی ارزی'!$E$4:$E$1036,$D$18,'ریز نقدینگی ارزی'!$B$4:$B$1036,C19) -> 0 | E19: =SUMIFS('ریز نقدینگی ارزی'!$F$4:$F$1036,'ریز نقدینگی ارزی'!$F$4:$F$1036,">0",'ریز نقدینگی ارزی'!$C$4:$C$1036,B19,'ریز نقدینگی ارزی'!$E$4:$E$1036,$E$18,'ریز نقدینگی ارزی'!$B$4:$B$1036,C19)-SUMIFS('ریز نقدینگی ارزی'!$G$4:$G$1036,'ریز نقدینگی ارزی'!$G$4:$G$1036,">0",'ریز نقدینگی ارزی'!$C$4:$C$1036,B19,'ریز نقدینگی ارزی'!$E$4:$E$1036,$E$18,'ریز نقدینگی ارزی'!$B$4:$B$1036,C19) -> 0 | F19: =SUMIFS('ریز نقدینگی ارزی'!$F$4:$F$1036,'ریز نقدینگی ارزی'!$F$4:$F$1036,">0",'ریز نقدینگی ارزی'!$C$4:$C$1036,B19,'ریز نقدینگی ارزی'!$E$4:$E$1036,$F$18,'ریز نقدینگی ارزی'!$B$4:$B$1036,C19)-SUMIFS('ریز نقدینگی ارزی'!$G$4:$G$1036,'ریز نقدینگی ارزی'!$G$4:$G$1036,">0",'ریز نقدینگی ارزی'!$C$4:$C$1036,B19,'ریز نقدینگی ارزی'!$E$4:$E$1036,$F$18,'ریز نقدینگی ارزی'!$B$4:$B$1036,C19) -> 0 | G19: =SUMIFS('ریز نقدینگی ارزی'!$F$4:$F$1036,'ریز نقدینگی ارزی'!$F$4:$F$1036,">0",'ریز نقدینگی ارزی'!$C$4:$C$1036,B19,'ریز نقدینگی ارزی'!$E$4:$E$1036,$G$18,'ریز نقدینگی ارزی'!$B$4:$B$1036,C19)-SUMIFS('ریز نقدینگی ارزی'!$G$4:$G$1036,'ریز نقدینگی ارزی'!$G$4:$G$1036,">0",'ریز نقدینگی ارزی'!$C$4:$C$1036,B19,'ریز نقدینگی ارزی'!$E$4:$E$1036,$G$18,'ریز نقدینگی ارزی'!$B$4:$B$1036,C19) -> 0 | H19: =SUMIFS('ریز نقدینگی ارزی'!$F$4:$F$1036,'ریز نقدینگی ارزی'!$F$4:$F$1036,">0",'ریز نقدینگی ارزی'!$C$4:$C$1036,B19,'ریز نقدینگی ارزی'!$E$4:$E$1036,$H$18,'ریز نقدینگی ارزی'!$B$4:$B$1036,C19)-SUMIFS('ریز نقدینگی ارزی'!$G$4:$G$1036,'ریز نقدینگی ارزی'!$G$4:$G$1036,">0",'ریز نقدینگی ارزی'!$C$4:$C$1036,B19,'ریز نقدینگی ارزی'!$E$4:$E$1036,$H$18,'ریز نقدینگی ارزی'!$B$4:$B$1036,C19) -> 0 | I19: =SUMIFS('ریز نقدینگی ارزی'!$F$4:$F$1036,'ریز نقدینگی ارزی'!$F$4:$F$1036,">0",'ریز نقدینگی ارزی'!$C$4:$C$1036,B19,'ریز نقدینگی ارزی'!$E$4:$E$1036,$I$18,'ریز نقدینگی ارزی'!$B$4:$B$1036,C19)-SUMIFS('ریز نقدینگی ارزی'!$G$4:$G$1036,'ریز نقدینگی ارزی'!$G$4:$G$1036,">0",'ریز نقدینگی ارزی'!$C$4:$C$1036,B19,'ریز نقدینگی ارزی'!$E$4:$E$1036,$I$18,'ریز نقدینگی ارزی'!$B$4:$B$1036,C19) -> 0 | J19: =SUMIFS('ریز نقدینگی ارزی'!$F$4:$F$1036,'ریز نقدینگی ارزی'!$F$4:$F$1036,">0",'ریز نقدینگی ارزی'!$C$4:$C$1036,B19,'ریز نقدینگی ارزی'!$E$4:$E$1036,$J$18,'ریز نقدینگی ارزی'!$B$4:$B$1036,C19)-SUMIFS('ریز نقدینگی ارزی'!$G$4:$G$1036,'ریز نقدینگی ارزی'!$G$4:$G$1036,">0",'ریز نقدینگی ارزی'!$C$4:$C$1036,B19,'ریز نقدینگی ارزی'!$E$4:$E$1036,$J$18,'ریز نقدینگی ارزی'!$B$4:$B$1036,C19) -> 0 | K19: =SUM(Table2[[#This Row],[تولید]:[مدیریت]]) -> 0
B20: Project 1 | C20: ¥ | D20: =SUMIFS('ریز نقدینگی ارزی'!$F$4:$F$1036,'ریز نقدینگی ارزی'!$F$4:$F$1036,">0",'ریز نقدینگی ارزی'!$C$4:$C$1036,B20,'ریز نقدینگی ارزی'!$E$4:$E$1036,$D$18,'ریز نقدینگی ارزی'!$B$4:$B$1036,C20)-SUMIFS('ریز نقدینگی ارزی'!$G$4:$G$1036,'ریز نقدینگی ارزی'!$G$4:$G$1036,">0",'ریز نقدینگی ارزی'!$C$4:$C$1036,B20,'ریز نقدینگی ارزی'!$E$4:$E$1036,$D$18,'ریز نقدینگی ارزی'!$B$4:$B$1036,C20) -> 0 | E20: =SUMIFS('ریز نقدینگی ارزی'!$F$4:$F$1036,'ریز نقدینگی ارزی'!$F$4:$F$1036,">0",'ریز نقدینگی ارزی'!$C$4:$C$1036,B20,'ریز نقدینگی ارزی'!$E$4:$E$1036,$E$18,'ریز نقدینگی ارزی'!$B$4:$B$1036,C20)-SUMIFS('ریز نقدینگی ارزی'!$G$4:$G$1036,'ریز نقدینگی ارزی'!$G$4:$G$1036,">0",'ریز نقدینگی ارزی'!$C$4:$C$1036,B20,'ریز نقدینگی ارزی'!$E$4:$E$1036,$E$18,'ریز نقدینگی ارزی'!$B$4:$B$1036,C20) -> 0 | F20: =SUMIFS('ریز نقدینگی ارزی'!$F$4:$F$1036,'ریز نقدینگی ارزی'!$F$4:$F$1036,">0",'ریز نقدینگی ارزی'!$C$4:$C$1036,B20,'ریز نقدینگی ارزی'!$E$4:$E$1036,$F$18,'ریز نقدینگی ارزی'!$B$4:$B$1036,C20)-SUMIFS('ریز نقدینگی ارزی'!$G$4:$G$1036,'ریز نقدینگی ارزی'!$G$4:$G$1036,">0",'ریز نقدینگی ارزی'!$C$4:$C$1036,B20,'ریز نقدینگی ارزی'!$E$4:$E$1036,$F$18,'ریز نقدینگی ارزی'!$B$4:$B$1036,C20) -> 0 | G20: =SUMIFS('ریز نقدینگی ارزی'!$F$4:$F$1036,'ریز نقدینگی ارزی'!$F$4:$F$1036,">0",'ریز نقدینگی ارزی'!$C$4:$C$1036,B20,'ریز نقدینگی ارزی'!$E$4:$E$1036,$G$18,'ریز نقدینگی ارزی'!$B$4:$B$1036,C20)-SUMIFS('ریز نقدینگی ارزی'!$G$4:$G$1036,'ریز نقدینگی ارزی'!$G$4:$G$1036,">0",'ریز نقدینگی ارزی'!$C$4:$C$1036,B20,'ریز نقدینگی ارزی'!$E$4:$E$1036,$G$18,'ریز نقدینگی ارزی'!$B$4:$B$1036,C20) -> 0 | H20: =SUMIFS('ریز نقدینگی ارزی'!$F$4:$F$1036,'ریز نقدینگی ارزی'!$F$4:$F$1036,">0",'ریز نقدینگی ارزی'!$C$4:$C$1036,B20,'ریز نقدینگی ارزی'!$E$4:$E$1036,$H$18,'ریز نقدینگی ارزی'!$B$4:$B$1036,C20)-SUMIFS('ریز نقدینگی ارزی'!$G$4:$G$1036,'ریز نقدینگی ارزی'!$G$4:$G$1036,">0",'ریز نقدینگی ارزی'!$C$4:$C$1036,B20,'ریز نقدینگی ارزی'!$E$4:$E$1036,$H$18,'ریز نقدینگی ارزی'!$B$4:$B$1036,C20) -> 0 | I20: =SUMIFS('ریز نقدینگی ارزی'!$F$4:$F$1036,'ریز نقدینگی ارزی'!$F$4:$F$1036,">0",'ریز نقدینگی ارزی'!$C$4:$C$1036,B20,'ریز نقدینگی ارزی'!$E$4:$E$1036,$I$18,'ریز نقدینگی ارزی'!$B$4:$B$1036,C20)-SUMIFS('ریز نقدینگی ارزی'!$G$4:$G$1036,'ریز نقدینگی ارزی'!$G$4:$G$1036,">0",'ریز نقدینگی ارزی'!$C$4:$C$1036,B20,'ریز نقدینگی ارزی'!$E$4:$E$1036,$I$18,'ریز نقدینگی ارزی'!$B$4:$B$1036,C20) -> 0 | J20: =SUMIFS('ریز نقدینگی ارزی'!$F$4:$F$1036,'ریز نقدینگی ارزی'!$F$4:$F$1036,">0",'ریز نقدینگی ارزی'!$C$4:$C$1036,B20,'ریز نقدینگی ارزی'!$E$4:$E$1036,$J$18,'ریز نقدینگی ارزی'!$B$4:$B$1036,C20)-SUMIFS('ریز نقدینگی ارزی'!$G$4:$G$1036,'ریز نقدینگی ارزی'!$G$4:$G$1036,">0",'ریز نقدینگی ارزی'!$C$4:$C$1036,B20,'ریز نقدینگی ارزی'!$E$4:$E$1036,$J$18,'ریز نقدینگی ارزی'!$B$4:$B$1036,C20) -> 0 | K20: =SUM(Table2[[#This Row],[تولید]:[مدیریت]]) -> 0
B21: Project 1 | C21: € | D21: =SUMIFS('ریز نقدینگی ارزی'!$F$4:$F$1036,'ریز نقدینگی ارزی'!$F$4:$F$1036,">0",'ریز نقدینگی ارزی'!$C$4:$C$1036,B21,'ریز نقدینگی ارزی'!$E$4:$E$1036,$D$18,'ریز نقدینگی ارزی'!$B$4:$B$1036,C21)-SUMIFS('ریز نقدینگی ارزی'!$G$4:$G$1036,'ریز نقدینگی ارزی'!$G$4:$G$1036,">0",'ریز نقدینگی ارزی'!$C$4:$C$1036,B21,'ریز نقدینگی ارزی'!$E$4:$E$1036,$D$18,'ریز نقدینگی ارزی'!$B$4:$B$1036,C21) -> 0 | E21: =SUMIFS('ریز نقدینگی ارزی'!$F$4:$F$1036,'ریز نقدینگی ارزی'!$F$4:$F$1036,">0",'ریز نقدینگی ارزی'!$C$4:$C$1036,B21,'ریز نقدینگی ارزی'!$E$4:$E$1036,$E$18,'ریز نقدینگی ارزی'!$B$4:$B$1036,C21)-SUMIFS('ریز نقدینگی ارزی'!$G$4:$G$1036,'ریز نقدینگی ارزی'!$G$4:$G$1036,">0",'ریز نقدینگی ارزی'!$C$4:$C$1036,B21,'ریز نقدینگی ارزی'!$E$4:$E$1036,$E$18,'ریز نقدینگی ارزی'!$B$4:$B$1036,C21) -> 435.27 | F21: =SUMIFS('ریز نقدینگی ارزی'!$F$4:$F$1036,'ریز نقدینگی ارزی'!$F$4:$F$1036,">0",'ریز نقدینگی ارزی'!$C$4:$C$1036,B21,'ریز نقدینگی ارزی'!$E$4:$E$1036,$F$18,'ریز نقدینگی ارزی'!$B$4:$B$1036,C21)-SUMIFS('ریز نقدینگی ارزی'!$G$4:$G$1036,'ریز نقدینگی ارزی'!$G$4:$G$1036,">0",'ریز نقدینگی ارزی'!$C$4:$C$1036,B21,'ریز نقدینگی ارزی'!$E$4:$E$1036,$F$18,'ریز نقدینگی ارزی'!$B$4:$B$1036,C21) -> 0 | G21: =SUMIFS('ریز نقدینگی ارزی'!$F$4:$F$1036,'ریز نقدینگی ارزی'!$F$4:$F$1036,">0",'ریز نقدینگی ارزی'!$C$4:$C$1036,B21,'ریز نقدینگی ارزی'!$E$4:$E$1036,$G$18,'ریز نقدینگی ارزی'!$B$4:$B$1036,C21)-SUMIFS('ریز نقدینگی ارزی'!$G$4:$G$1036,'ریز نقدینگی ارزی'!$G$4:$G$1036,">0",'ریز نقدینگی ارزی'!$C$4:$C$1036,B21,'ریز نقدینگی ارزی'!$E$4:$E$1036,$G$18,'ریز نقدینگی ارزی'!$B$4:$B$1036,C21) -> 0 | H21: =SUMIFS('ریز نقدینگی ارزی'!$F$4:$F$1036,'ریز نقدینگی ارزی'!$F$4:$F$1036,">0",'ریز نقدینگی ارزی'!$C$4:$C$1036,B21,'ریز نقدینگی ارزی'!$E$4:$E$1036,$H$18,'ریز نقدینگی ارزی'!$B$4:$B$1036,C21)-SUMIFS('ریز نقدینگی ارزی'!$G$4:$G$1036,'ریز نقدینگی ارزی'!$G$4:$G$1036,">0",'ریز نقدینگی ارزی'!$C$4:$C$1036,B21,'ریز نقدینگی ارزی'!$E$4:$E$1036,$H$18,'ریز نقدینگی ارزی'!$B$4:$B$1036,C21) -> 0 | I21: =SUMIFS('ریز نقدینگی ارزی'!$F$4:$F$1036,'ریز نقدینگی ارزی'!$F$4:$F$1036,">0",'ریز نقدینگی ارزی'!$C$4:$C$1036,B21,'ریز نقدینگی ارزی'!$E$4:$E$1036,$I$18,'ریز نقدینگی ارزی'!$B$4:$B$1036,C21)-SUMIFS('ریز نقدینگی ارزی'!$G$4:$G$1036,'ریز نقدینگی ارزی'!$G$4:$G$1036,">0",'ریز نقدینگی ارزی'!$C$4:$C$1036,B21,'ریز نقدینگی ارزی'!$E$4:$E$1036,$I$18,'ریز نقدینگی ارزی'!$B$4:$B$1036,C21) -> 577 | J21: =SUMIFS('ریز نقدینگی ارزی'!$F$4:$F$1036,'ریز نقدینگی ارزی'!$F$4:$F$1036,">0",'ریز نقدینگی ارزی'!$C$4:$C$1036,B21,'ریز نقدینگی ارزی'!$E$4:$E$1036,$J$18,'ریز نقدینگی ارزی'!$B$4:$B$1036,C21)-SUMIFS('ریز نقدینگی ارزی'!$G$4:$G$1036,'ریز نقدینگی ارزی'!$G$4:$G$1036,">0",'ریز نقدینگی ارزی'!$C$4:$C$1036,B21,'ریز نقدینگی ارزی'!$E$4:$E$1036,$J$18,'ریز نقدینگی ارزی'!$B$4:$B$1036,C21) -> 0 | K21: =SUM(Table2[[#This Row],[تولید]:[مدیریت]]) -> 1012.27
B22: Project 1 | C22: AED | D22: =SUMIFS('ریز نقدینگی ارزی'!$F$4:$F$1036,'ریز نقدینگی ارزی'!$F$4:$F$1036,">0",'ریز نقدینگی ارزی'!$C$4:$C$1036,B22,'ریز نقدینگی ارزی'!$E$4:$E$1036,$D$18,'ریز نقدینگی ارزی'!$B$4:$B$1036,C22)-SUMIFS('ریز نقدینگی ارزی'!$G$4:$G$1036,'ریز نقدینگی ارزی'!$G$4:$G$1036,">0",'ریز نقدینگی ارزی'!$C$4:$C$1036,B22,'ریز نقدینگی ارزی'!$E$4:$E$1036,$D$18,'ریز نقدینگی ارزی'!$B$4:$B$1036,C22) -> 1 | E22: =SUMIFS('ریز نقدینگی ارزی'!$F$4:$F$1036,'ریز نقدینگی ارزی'!$F$4:$F$1036,">0",'ریز نقدینگی ارزی'!$C$4:$C$1036,B22,'ریز نقدینگی ارزی'!$E$4:$E$1036,$E$18,'ریز نقدینگی ارزی'!$B$4:$B$1036,C22)-SUMIFS('ریز نقدینگی ارزی'!$G$4:$G$1036,'ریز نقدینگی ارزی'!$G$4:$G$1036,">0",'ریز نقدینگی ارزی'!$C$4:$C$1036,B22,'ریز نقدینگی ارزی'!$E$4:$E$1036,$E$18,'ریز نقدینگی ارزی'!$B$4:$B$1036,C22) -> 435.6 | F22: =SUMIFS('ریز نقدینگی ارزی'!$F$4:$F$1036,'ریز نقدینگی ارزی'!$F$4:$F$1036,">0",'ریز نقدینگی ارزی'!$C$4:$C$1036,B22,'ریز نقدینگی ارزی'!$E$4:$E$1036,$F$18,'ریز نقدینگی ارزی'!$B$4:$B$1036,C22)-SUMIFS('ریز نقدینگی ارزی'!$G$4:$G$1036,'ریز نقدینگی ارزی'!$G$4:$G$1036,">0",'ریز نقدینگی ارزی'!$C$4:$C$1036,B22,'ریز نقدینگی ارزی'!$E$4:$E$1036,$F$18,'ریز نقدینگی ارزی'!$B$4:$B$1036,C22) -> 0 | G22: =SUMIFS('ریز نقدینگی ارزی'!$F$4:$F$1036,'ریز نقدینگی ارزی'!$F$4:$F$1036,">0",'ریز نقدینگی ارزی'!$C$4:$C$1036,B22,'ریز نقدینگی ارزی'!$E$4:$E$1036,$G$18,'ریز نقدینگی ارزی'!$B$4:$B$1036,C22)-SUMIFS('ریز نقدینگی ارزی'!$G$4:$G$1036,'ریز نقدینگی ارزی'!$G$4:$G$1036,">0",'ریز نقدینگی ارزی'!$C$4:$C$1036,B22,'ریز نقدینگی ارزی'!$E$4:$E$1036,$G$18,'ریز نقدینگی ارزی'!$B$4:$B$1036,C22) -> 0 | H22: =SUMIFS('ریز نقدینگی ارزی'!$F$4:$F$1036,'ریز نقدینگی ارزی'!$F$4:$F$1036,">0",'ریز نقدینگی ارزی'!$C$4:$C$1036,B22,'ریز نقدینگی ارزی'!$E$4:$E$1036,$H$18,'ریز نقدینگی ارزی'!$B$4:$B$1036,C22)-SUMIFS('ریز نقدینگی ارزی'!$G$4:$G$1036,'ریز نقدینگی ارزی'!$G$4:$G$1036,">0",'ریز نقدینگی ارزی'!$C$4:$C$1036,B22,'ریز نقدینگی ارزی'!$E$4:$E$1036,$H$18,'ریز نقدینگی ارزی'!$B$4:$B$1036,C22) -> 191.2 | I22: =SUMIFS('ریز نقدینگی ارزی'!$F$4:$F$1036,'ریز نقدینگی ارزی'!$F$4:$F$1036,">0",'ریز نقدینگی ارزی'!$C$4:$C$1036,B22,'ریز نقدینگی ارزی'!$E$4:$E$1036,$I$18,'ریز نقدینگی ارزی'!$B$4:$B$1036,C22)-SUMIFS('ریز نقدینگی ارزی'!$G$4:$G$1036,'ریز نقدینگی ارزی'!$G$4:$G$1036,">0",'ریز نقدینگی ارزی'!$C$4:$C$1036,B22,'ریز نقدینگی ارزی'!$E$4:$E$1036,$I$18,'ریز نقدینگی ارزی'!$B$4:$B$1036,C22) -> 305.2 | J22: =SUMIFS('ریز نقدینگی ارزی'!$F$4:$F$1036,'ریز نقدینگی ارزی'!$F$4:$F$1036,">0",'ریز نقدینگی ارزی'!$C$4:$C$1036,B22,'ریز نقدینگی ارزی'!$E$4:$E$1036,$J$18,'ریز نقدینگی ارزی'!$B$4:$B$1036,C22)-SUMIFS('ریز نقدینگی ارزی'!$G$4:$G$1036,'ریز نقدینگی ارزی'!$G$4:$G$1036,">0",'ریز نقدینگی ارزی'!$C$4:$C$1036,B22,'ریز نقدینگی ارزی'!$E$4:$E$1036,$J$18,'ریز نقدینگی ارزی'!$B$4:$B$1036,C22) -> 0 | K22: =SUM(Table2[[#This Row],[تولید]:[مدیریت]]) -> 933
B23: Project 2 | C23: $ | D23: =SUMIFS('ریز نقدینگی ارزی'!$F$4:$F$1036,'ریز نقدینگی ارزی'!$F$4:$F$1036,">0",'ریز نقدینگی ارزی'!$C$4:$C$1036,B23,'ریز نقدینگی ارزی'!$E$4:$E$1036,$D$18,'ریز نقدینگی ارزی'!$B$4:$B$1036,C23)-SUMIFS('ریز نقدینگی ارزی'!$G$4:$G$1036,'ریز نقدینگی ارزی'!$G$4:$G$1036,">0",'ریز نقدینگی ارزی'!$C$4:$C$1036,B23,'ریز نقدینگی ارزی'!$E$4:$E$1036,$D$18,'ریز نقدینگی ارزی'!$B$4:$B$1036,C23) -> 0 | E23: =SUMIFS('ریز نقدینگی ارزی'!$F$4:$F$1036,'ریز نقدینگی ارزی'!$F$4:$F$1036,">0",'ریز نقدینگی ارزی'!$C$4:$C$1036,B23,'ریز نقدینگی ارزی'!$E$4:$E$1036,$E$18,'ریز نقدینگی ارزی'!$B$4:$B$1036,C23)-SUMIFS('ریز نقدینگی ارزی'!$G$4:$G$1036,'ریز نقدینگی ارزی'!$G$4:$G$1036,">0",'ریز نقدینگی ارزی'!$C$4:$C$1036,B23,'ریز نقدینگی ارزی'!$E$4:$E$1036,$E$18,'ریز نقدینگی ارزی'!$B$4:$B$1036,C23) -> 835.2 | F23: =SUMIFS('ریز نقدینگی ارزی'!$F$4:$F$1036,'ریز نقدینگی ارزی'!$F$4:$F$1036,">0",'ریز نقدینگی ارزی'!$C$4:$C$1036,B23,'ریز نقدینگی ارزی'!$E$4:$E$1036,$F$18,'ریز نقدینگی ارزی'!$B$4:$B$1036,C23)-SUMIFS('ریز نقدینگی ارزی'!$G$4:$G$1036,'ریز نقدینگی ارزی'!$G$4:$G$1036,">0",'ریز نقدینگی ارزی'!$C$4:$C$1036,B23,'ریز نقدینگی ارزی'!$E$4:$E$1036,$F$18,'ریز نقدینگی ارزی'!$B$4:$B$1036,C23) -> 0 | G23: =SUMIFS('ریز نقدینگی ارزی'!$F$4:$F$1036,'ریز نقدینگی ارزی'!$F$4:$F$1036,">0",'ریز نقدینگی ارزی'!$C$4:$C$1036,B23,'ریز نقدینگی ارزی'!$E$4:$E$1036,$G$18,'ریز نقدینگی ارزی'!$B$4:$B$1036,C23)-SUMIFS('ریز نقدینگی ارزی'!$G$4:$G$1036,'ریز نقدینگی ارزی'!$G$4:$G$1036,">0",'ریز نقدینگی ارزی'!$C$4:$C$1036,B23,'ریز نقدینگی ارزی'!$E$4:$E$1036,$G$18,'ریز نقدینگی ارزی'!$B$4:$B$1036,C23) -> 0 | H23: =SUMIFS('ریز نقدینگی ارزی'!$F$4:$F$1036,'ریز نقدینگی ارزی'!$F$4:$F$1036,">0",'ریز نقدینگی ارزی'!$C$4:$C$1036,B23,'ریز نقدینگی ارزی'!$E$4:$E$1036,$H$18,'ریز نقدینگی ارزی'!$B$4:$B$1036,C23)-SUMIFS('ریز نقدینگی ارزی'!$G$4:$G$1036,'ریز نقدینگی ارزی'!$G$4:$G$1036,">0",'ریز نقدینگی ارزی'!$C$4:$C$1036,B23,'ریز نقدینگی ارزی'!$E$4:$E$1036,$H$18,'ریز نقدینگی ارزی'!$B$4:$B$1036,C23) -> 0 | I23: =SUMIFS('ریز نقدینگی ارزی'!$F$4:$F$1036,'ریز نقدینگی ارزی'!$F$4:$F$1036,">0",'ریز نقدینگی ارزی'!$C$4:$C$1036,B23,'ریز نقدینگی ارزی'!$E$4:$E$1036,$I$18,'ریز نقدینگی ارزی'!$B$4:$B$1036,C23)-SUMIFS('ریز نقدینگی ارزی'!$G$4:$G$1036,'ریز نقدینگی ارزی'!$G$4:$G$1036,">0",'ریز نقدینگی ارزی'!$C$4:$C$1036,B23,'ریز نقدینگی ارزی'!$E$4:$E$1036,$I$18,'ریز نقدینگی ارزی'!$B$4:$B$1036,C23) -> 0 | J23: =SUMIFS('ریز نقدینگی ارزی'!$F$4:$F$1036,'ریز نقدینگی ارزی'!$F$4:$F$1036,">0",'ریز نقدینگی ارزی'!$C$4:$C$1036,B23,'ریز نقدینگی ارزی'!$E$4:$E$1036,$J$18,'ریز نقدینگی ارزی'!$B$4:$B$1036,C23)-SUMIFS('ریز نقدینگی ارزی'!$G$4:$G$1036,'ریز نقدینگی ارزی'!$G$4:$G$1036,">0",'ریز نقدینگی ارزی'!$C$4:$C$1036,B23,'ریز نقدینگی ارزی'!$E$4:$E$1036,$J$18,'ریز نقدینگی ارزی'!$B$4:$B$1036,C23) -> 0 | K23: =SUM(Table2[[#This Row],[تولید]:[مدیریت]]) -> 835.2
B24: Project 2 | C24: ¥ | D24: =SUMIFS('ریز نقدینگی ارزی'!$F$4:$F$1036,'ریز نقدینگی ارزی'!$F$4:$F$1036,">0",'ریز نقدینگی ارزی'!$C$4:$C$1036,B24,'ریز نقدینگی ارزی'!$E$4:$E$1036,$D$18,'ریز نقدینگی ارزی'!$B$4:$B$1036,C24)-SUMIFS('ریز نقدینگی ارزی'!$G$4:$G$1036,'ریز نقدینگی ارزی'!$G$4:$G$1036,">0",'ریز نقدینگی ارزی'!$C$4:$C$1036,B24,'ریز نقدینگی ارزی'!$E$4:$E$1036,$D$18,'ریز نقدینگی ارزی'!$B$4:$B$1036,C24) -> 0 | E24: =SUMIFS('ریز نقدینگی ارزی'!$F$4:$F$1036,'ریز نقدینگی ارزی'!$F$4:$F$1036,">0",'ریز نقدینگی ارزی'!$C$4:$C$1036,B24,'ریز نقدینگی ارزی'!$E$4:$E$1036,$E$18,'ریز نقدینگی ارزی'!$B$4:$B$1036,C24)-SUMIFS('ریز نقدینگی ارزی'!$G$4:$G$1036,'ریز نقدینگی ارزی'!$G$4:$G$1036,">0",'ریز نقدینگی ارزی'!$C$4:$C$1036,B24,'ریز نقدینگی ارزی'!$E$4:$E$1036,$E$18,'ریز نقدینگی ارزی'!$B$4:$B$1036,C24) -> 321.9 | F24: =SUMIFS('ریز نقدینگی ارزی'!$F$4:$F$1036,'ریز نقدینگی ارزی'!$F$4:$F$1036,">0",'ریز نقدینگی ارزی'!$C$4:$C$1036,B24,'ریز نقدینگی ارزی'!$E$4:$E$1036,$F$18,'ریز نقدینگی ارزی'!$B$4:$B$1036,C24)-SUMIFS('ریز نقدینگی ارزی'!$G$4:$G$1036,'ریز نقدینگی ارزی'!$G$4:$G$1036,">0",'ریز نقدینگی ارزی'!$C$4:$C$1036,B24,'ریز نقدینگی ارزی'!$E$4:$E$1036,$F$18,'ریز نقدینگی ارزی'!$B$4:$B$1036,C24) -> 0 | G24: =SUMIFS('ریز نقدینگی ارزی'!$F$4:$F$1036,'ریز نقدینگی ارزی'!$F$4:$F$1036,">0",'ریز نقدینگی ارزی'!$C$4:$C$1036,B24,'ریز نقدینگی ارزی'!$E$4:$E$1036,$G$18,'ریز نقدینگی ارزی'!$B$4:$B$1036,C24)-SUMIFS('ریز نقدینگی ارزی'!$G$4:$G$1036,'ریز نقدینگی ارزی'!$G$4:$G$1036,">0",'ریز نقدینگی ارزی'!$C$4:$C$1036,B24,'ریز نقدینگی ارزی'!$E$4:$E$1036,$G$18,'ریز نقدینگی ارزی'!$B$4:$B$1036,C24) -> 0 | H24: =SUMIFS('ریز نقدینگی ارزی'!$F$4:$F$1036,'ریز نقدینگی ارزی'!$F$4:$F$1036,">0",'ریز نقدینگی ارزی'!$C$4:$C$1036,B24,'ریز نقدینگی ارزی'!$E$4:$E$1036,$H$18,'ریز نقدینگی ارزی'!$B$4:$B$1036,C24)-SUMIFS('ریز نقدینگی ارزی'!$G$4:$G$1036,'ریز نقدینگی ارزی'!$G$4:$G$1036,">0",'ریز نقدینگی ارزی'!$C$4:$C$1036,B24,'ریز نقدینگی ارزی'!$E$4:$E$1036,$H$18,'ریز نقدینگی ارزی'!$B$4:$B$1036,C24) -> 0 | I24: =SUMIFS('ریز نقدینگی ارزی'!$F$4:$F$1036,'ریز نقدینگی ارزی'!$F$4:$F$1036,">0",'ریز نقدینگی ارزی'!$C$4:$C$1036,B24,'ریز نقدینگی ارزی'!$E$4:$E$1036,$I$18,'ریز نقدینگی ارزی'!$B$4:$B$1036,C24)-SUMIFS('ریز نقدینگی ارزی'!$G$4:$G$1036,'ریز نقدینگی ارزی'!$G$4:$G$1036,">0",'ریز نقدینگی ارزی'!$C$4:$C$1036,B24,'ریز نقدینگی ارزی'!$E$4:$E$1036,$I$18,'ریز نقدینگی ارزی'!$B$4:$B$1036,C24) -> 0 | J24: =SUMIFS('ریز نقدینگی ارزی'!$F$4:$F$1036,'ریز نقدینگی ارزی'!$F$4:$F$1036,">0",'ریز نقدینگی ارزی'!$C$4:$C$1036,B24,'ریز نقدینگی ارزی'!$E$4:$E$1036,$J$18,'ریز نقدینگی ارزی'!$B$4:$B$1036,C24)-SUMIFS('ریز نقدینگی ارزی'!$G$4:$G$1036,'ریز نقدینگی ارزی'!$G$4:$G$1036,">0",'ریز نقدینگی ارزی'!$C$4:$C$1036,B24,'ریز نقدینگی ارزی'!$E$4:$E$1036,$J$18,'ریز نقدینگی ارزی'!$B$4:$B$1036,C24) -> 0 | K24: =SUM(Table2[[#This Row],[تولید]:[مدیریت]]) -> 321.9
B25: Project 2 | C25: € | D25: =SUMIFS('ریز نقدینگی ارزی'!$F$4:$F$1036,'ریز نقدینگی ارزی'!$F$4:$F$1036,">0",'ریز نقدینگی ارزی'!$C$4:$C$1036,B25,'ریز نقدینگی ارزی'!$E$4:$E$1036,$D$18,'ریز نقدینگی ارزی'!$B$4:$B$1036,C25)-SUMIFS('ریز نقدینگی ارزی'!$G$4:$G$1036,'ریز نقدینگی ارزی'!$G$4:$G$1036,">0",'ریز نقدینگی ارزی'!$C$4:$C$1036,B25,'ریز نقدینگی ارزی'!$E$4:$E$1036,$D$18,'ریز نقدینگی ارزی'!$B$4:$B$1036,C25) -> 0 | E25: =SUMIFS('ریز نقدینگی ارزی'!$F$4:$F$1036,'ریز نقدینگی ارزی'!$F$4:$F$1036,">0",'ریز نقدینگی ارزی'!$C$4:$C$1036,B25,'ریز نقدینگی ارزی'!$E$4:$E$1036,$E$18,'ریز نقدینگی ارزی'!$B$4:$B$1036,C25)-SUMIFS('ریز نقدینگی ارزی'!$G$4:$G$1036,'ریز نقدینگی ارزی'!$G$4:$G$1036,">0",'ریز نقدینگی ارزی'!$C$4:$C$1036,B25,'ریز نقدینگی ارزی'!$E$4:$E$1036,$E$18,'ریز نقدینگی ارزی'!$B$4:$B$1036,C25) -> 0 | F25: =SUMIFS('ریز نقدینگی ارزی'!$F$4:$F$1036,'ریز نقدینگی ارزی'!$F$4:$F$1036,">0",'ریز نقدینگی ارزی'!$C$4:$C$1036,B25,'ریز نقدینگی ارزی'!$E$4:$E$1036,$F$18,'ریز نقدینگی ارزی'!$B$4:$B$1036,C25)-SUMIFS('ریز نقدینگی ارزی'!$G$4:$G$1036,'ریز نقدینگی ارزی'!$G$4:$G$1036,">0",'ریز نقدینگی ارزی'!$C$4:$C$1036,B25,'ریز نقدینگی ارزی'!$E$4:$E$1036,$F$18,'ریز نقدینگی ارزی'!$B$4:$B$1036,C25) -> 0 | G25: =SUMIFS('ریز نقدینگی ارزی'!$F$4:$F$1036,'ریز نقدینگی ارزی'!$F$4:$F$1036,">0",'ریز نقدینگی ارزی'!$C$4:$C$1036,B25,'ریز نقدینگی ارزی'!$E$4:$E$1036,$G$18,'ریز نقدینگی ارزی'!$B$4:$B$1036,C25)-SUMIFS('ریز نقدینگی ارزی'!$G$4:$G$1036,'ریز نقدینگی ارزی'!$G$4:$G$1036,">0",'ریز نقدینگی ارزی'!$C$4:$C$1036,B25,'ریز نقدینگی ارزی'!$E$4:$E$1036,$G$18,'ریز نقدینگی ارزی'!$B$4:$B$1036,C25) -> 0 | H25: =SUMIFS('ریز نقدینگی ارزی'!$F$4:$F$1036,'ریز نقدینگی ارزی'!$F$4:$F$1036,">0",'ریز نقدینگی ارزی'!$C$4:$C$1036,B25,'ریز نقدینگی ارزی'!$E$4:$E$1036,$H$18,'ریز نقدینگی ارزی'!$B$4:$B$1036,C25)-SUMIFS('ریز نقدینگی ارزی'!$G$4:$G$1036,'ریز نقدینگی ارزی'!$G$4:$G$1036,">0",'ریز نقدینگی ارزی'!$C$4:$C$1036,B25,'ریز نقدینگی ارزی'!$E$4:$E$1036,$H$18,'ریز نقدینگی ارزی'!$B$4:$B$1036,C25) -> 0 | I25: =SUMIFS('ریز نقدینگی ارزی'!$F$4:$F$1036,'ریز نقدینگی ارزی'!$F$4:$F$1036,">0",'ریز نقدینگی ارزی'!$C$4:$C$1036,B25,'ریز نقدینگی ارزی'!$E$4:$E$1036,$I$18,'ریز نقدینگی ارزی'!$B$4:$B$1036,C25)-SUMIFS('ریز نقدینگی ارزی'!$G$4:$G$1036,'ریز نقدینگی ارزی'!$G$4:$G$1036,">0",'ریز نقدینگی ارزی'!$C$4:$C$1036,B25,'ریز نقدینگی ارزی'!$E$4:$E$1036,$I$18,'ریز نقدینگی ارزی'!$B$4:$B$1036,C25) -> 0 | J25: =SUMIFS('ریز نقدینگی ارزی'!$F$4:$F$1036,'ریز نقدینگی ارزی'!$F$4:$F$1036,">0",'ریز نقدینگی ارزی'!$C$4:$C$1036,B25,'ریز نقدینگی ارزی'!$E$4:$E$1036,$J$18,'ریز نقدینگی ارزی'!$B$4:$B$1036,C25)-SUMIFS('ریز نقدینگی ارزی'!$G$4:$G$1036,'ریز نقدینگی ارزی'!$G$4:$G$1036,">0",'ریز نقدینگی ارزی'!$C$4:$C$1036,B25,'ریز نقدینگی ارزی'!$E$4:$E$1036,$J$18,'ریز نقدینگی ارزی'!$B$4:$B$1036,C25) -> 0 | K25: =SUM(Table2[[#This Row],[تولید]:[مدیریت]]) -> 0
B26: Project 2 | C26: AED | D26: =SUMIFS('ریز نقدینگی ارزی'!$F$4:$F$1036,'ریز نقدینگی ارزی'!$F$4:$F$1036,">0",'ریز نقدینگی ارزی'!$C$4:$C$1036,B26,'ریز نقدینگی ارزی'!$E$4:$E$1036,$D$18,'ریز نقدینگی ارزی'!$B$4:$B$1036,C26)-SUMIFS('ریز نقدینگی ارزی'!$G$4:$G$1036,'ریز نقدینگی ارزی'!$G$4:$G$1036,">0",'ریز نقدینگی ارزی'!$C$4:$C$1036,B26,'ریز نقدینگی ارزی'!$E$4:$E$1036,$D$18,'ریز نقدینگی ارزی'!$B$4:$B$1036,C26) -> 7.1034483 | E26: =SUMIFS('ریز نقدینگی ارزی'!$F$4:$F$1036,'ریز نقدینگی ارزی'!$F$4:$F$1036,">0",'ریز نقدینگی ارزی'!$C$4:$C$1036,B26,'ریز نقدینگی ارزی'!$E$4:$E$1036,$E$18,'ریز نقدینگی ارزی'!$B$4:$B$1036,C26)-SUMIFS('ریز نقدینگی ارزی'!$G$4:$G$1036,'ریز نقدینگی ارزی'!$G$4:$G$1036,">0",'ریز نقدینگی ارزی'!$C$4:$C$1036,B26,'ریز نقدینگی ارزی'!$E$4:$E$1036,$E$18,'ریز نقدینگی ارزی'!$B$4:$B$1036,C26) -> 12.1 | F26: =SUMIFS('ریز نقدینگی ارزی'!$F$4:$F$1036,'ریز نقدینگی ارزی'!$F$4:$F$1036,">0",'ریز نقدینگی ارزی'!$C$4:$C$1036,B26,'ریز نقدینگی ارزی'!$E$4:$E$1036,$F$18,'ریز نقدینگی ارزی'!$B$4:$B$1036,C26)-SUMIFS('ریز نقدینگی ارزی'!$G$4:$G$1036,'ریز نقدینگی ارزی'!$G$4:$G$1036,">0",'ریز نقدینگی ارزی'!$C$4:$C$1036,B26,'ریز نقدینگی ارزی'!$E$4:$E$1036,$F$18,'ریز نقدینگی ارزی'!$B$4:$B$1036,C26) -> 0 | G26: =SUMIFS('ریز نقدینگی ارزی'!$F$4:$F$1036,'ریز نقدینگی ارزی'!$F$4:$F$1036,">0",'ریز نقدینگی ارزی'!$C$4:$C$1036,B26,'ریز نقدینگی ارزی'!$E$4:$E$1036,$G$18,'ریز نقدینگی ارزی'!$B$4:$B$1036,C26)-SUMIFS('ریز نقدینگی ارزی'!$G$4:$G$1036,'ریز نقدینگی ارزی'!$G$4:$G$1036,">0",'ریز نقدینگی ارزی'!$C$4:$C$1036,B26,'ریز نقدینگی ارزی'!$E$4:$E$1036,$G$18,'ریز نقدینگی ارزی'!$B$4:$B$1036,C26) -> 0 | H26: =SUMIFS('ریز نقدینگی ارزی'!$F$4:$F$1036,'ریز نقدینگی ارزی'!$F$4:$F$1036,">0",'ریز نقدینگی ارزی'!$C$4:$C$1036,B26,'ریز نقدینگی ارزی'!$E$4:$E$1036,$H$18,'ریز نقدینگی ارزی'!$B$4:$B$1036,C26)-SUMIFS('ریز نقدینگی ارزی'!$G$4:$G$1036,'ریز نقدینگی ارزی'!$G$4:$G$1036,">0",'ریز نقدینگی ارزی'!$C$4:$C$1036,B26,'ریز نقدینگی ارزی'!$E$4:$E$1036,$H$18,'ریز نقدینگی ارزی'!$B$4:$B$1036,C26) -> 0 | I26: =SUMIFS('ریز نقدینگی ارزی'!$F$4:$F$1036,'ریز نقدینگی ارزی'!$F$4:$F$1036,">0",'ریز نقدینگی ارزی'!$C$4:$C$1036,B26,'ریز نقدینگی ارزی'!$E$4:$E$1036,$I$18,'ریز نقدینگی ارزی'!$B$4:$B$1036,C26)-SUMIFS('ریز نقدینگی ارزی'!$G$4:$G$1036,'ریز نقدینگی ارزی'!$G$4:$G$1036,">0",'ریز نقدینگی ارزی'!$C$4:$C$1036,B26,'ریز نقدینگی ارزی'!$E$4:$E$1036,$I$18,'ریز نقدینگی ارزی'!$B$4:$B$1036,C26) -> 0 | J26: =SUMIFS('ریز نقدینگی ارزی'!$F$4:$F$1036,'ریز نقدینگی ارزی'!$F$4:$F$1036,">0",'ریز نقدینگی ارزی'!$C$4:$C$1036,B26,'ریز نقدینگی ارزی'!$E$4:$E$1036,$J$18,'ریز نقدینگی ارزی'!$B$4:$B$1036,C26)-SUMIFS('ریز نقدینگی ارزی'!$G$4:$G$1036,'ریز نقدینگی ارزی'!$G$4:$G$1036,">0",'ریز نقدینگی ارزی'!$C$4:$C$1036,B26,'ریز نقدینگی ارزی'!$E$4:$E$1036,$J$18,'ریز نقدینگی ارزی'!$B$4:$B$1036,C26) -> 0 | K26: =SUM(Table2[[#This Row],[تولید]:[مدیریت]]) -> 19.203448
B27: کارمزد بانکی | C27: $ | K27: ='ریز نقدینگی ارزی'!M66+'ریز نقدینگی ارزی'!M70 -> 0
B28: کارمزد بانکی | C28: ¥ | K28: ='ریز نقدینگی ارزی'!M67+'ریز نقدینگی ارزی'!M71 -> 0
B29: کارمزد بانکی | C29: € | K29: ='ریز نقدینگی ارزی'!M64+'ریز نقدینگی ارزی'!M68 -> 0
B30: کارمزد بانکی | C30: AED | K30: ='ریز نقدینگی ارزی'!M65+'ریز نقدینگی ارزی'!M69 -> 257
F32: عملیاتی | G32: مجموع عملیاتی $ | I32: =K19+K23 -> 835.2
G33: مجموع عملیاتی ¥ | I33: =K20+K24 -> 321.9
G34: مجموع عملیاتی € | I34: =K21+K25 -> 1012.27
G35: مجموع عملیاتی AED | I35: =K22+K26 -> 952.20345
F37: ستاد | G37: ستاد $ | I37: ='ریز نقدینگی ارزی'!M62-K27 -> 124.8
G38: ستاد ¥ | I38: ='ریز نقدینگی ارزی'!M63-K28 -> 48.1
G39: ستاد € | I39: ='ریز نقدینگی ارزی'!M60-K29 -> 67.73
G40: ستاد AED | I40: ='ریز نقدینگی ارزی'!M61-K30 -> 69.796552
F42: واریزی نامشخص | G42: واریزی نامشخص $ | I42: 16
G43: واریزی نامشخص ¥ | I43: 17
G44: واریزی نامشخص € | I44: 56
G45: واریزی نامشخص AED | I45: 138 | J45: 181225.55
F47: موجودی نقد | G47: موجودی نقد $ | I47: =I32+I37+I42 -> 976
G48: موجودی نقد ¥ | I48: =I33+I38+I43 -> 387
G49: موجودی نقد € | I49: =I34+I39+I44 -> 1136
G50: موجودی نقد AED | I50: =I35+I40+I45 -> 1160

Sheet قرض ارزی
B2: تاریخ به‌روز رسانی: 1405/04/09
B4: قرض و عودت قرض بین پروژه‌ها:
B5: کد پروژه کارفرما | C5: واکا (SBU) | D5: واکای طرف قرض | E5: کد پروژه طرف قرض | F5: ارز | G5: قرض گرفته | H5: قرض داده | I5: قرض پس گرفته | J5: قرض پس داده | K5: بازپرداخت قرض داده شده | L5: بازپرداخت قرض گرفته شده | M5: مانده قرض | N5: وضعیت
B6: Project 1 | C6: تولید | D6: تامین | E6: Project 1 | F6: AED | G6: =SUMIFS('ریز گزارش ارزی'!$AC$8:$AC$63,'ریز گزارش ارزی'!$AC$8:$AC$63,">0",'ریز گزارش ارزی'!$AG$8:$AG$63,"قرض",'ریز گزارش ارزی'!$H$8:$H$63,F6,'ریز گزارش ارزی'!$F$8:$F$63,B6,'ریز گزارش ارزی'!$G$8:$G$63,C6,'ریز گزارش ارزی'!$AO$8:$AO$63,D6,'ریز گزارش ارزی'!$AP$8:$AP$63,E6) -> 80 | H6: =SUMIFS('ریز گزارش ارزی'!$AD$8:$AD$63,'ریز گزارش ارزی'!$AD$8:$AD$63,">0",'ریز گزارش ارزی'!$AG$8:$AG$63,"قرض",'ریز گزارش ارزی'!$H$8:$H$63,F6,'ریز گزارش ارزی'!$F$8:$F$63,B6,'ریز گزارش ارزی'!$G$8:$G$63,C6,'ریز گزارش ارزی'!$AO$8:$AO$63,D6,'ریز گزارش ارزی'!$AP$8:$AP$63,E6) -> 0 | I6: =SUMIFS('ریز گزارش ارزی'!$AC$8:$AC$63,'ریز گزارش ارزی'!$AC$8:$AC$63,">0",'ریز گزارش ارزی'!$AG$8:$AG$63,"عودت قرض",'ریز گزارش ارزی'!$H$8:$H$63,F6,'ریز گزارش ارزی'!$F$8:$F$63,B6,'ریز گزارش ارزی'!$G$8:$G$63,C6,'ریز گزارش ارزی'!$AO$8:$AO$63,D6,'ریز گزارش ارزی'!$AP$8:$AP$63,E6) -> 0 | J6: =SUMIFS('ریز گزارش ارزی'!$AD$8:$AD$63,'ریز گزارش ارزی'!$AD$8:$AD$63,">0",'ریز گزارش ارزی'!$AG$8:$AG$63,"عودت قرض",'ریز گزارش ارزی'!$H$8:$H$63,F6,'ریز گزارش ارزی'!$F$8:$F$63,B6,'ریز گزارش ارزی'!$G$8:$G$63,C6,'ریز گزارش ارزی'!$AO$8:$AO$63,D6,'ریز گزارش ارزی'!$AP$8:$AP$63,E6) -> 0 | K6: =H6-I6 -> 0 | L6: =G6-J6 -> 80 | M6: =K6-L6 -> -80 | N6: =IF(M6=0,"بی‌حساب",IF(M6>0,"طلبکار","بدهکار")) -> بدهکار
B7: Project 1 | C7: تولید | D7: نصب | E7: Project 1 | F7: AED | G7: =SUMIFS('ریز گزارش ارزی'!$AC$8:$AC$63,'ریز گزارش ارزی'!$AC$8:$AC$63,">0",'ریز گزارش ارزی'!$AG$8:$AG$63,"قرض",'ریز گزارش ارزی'!$H$8:$H$63,F7,'ریز گزارش ارزی'!$F$8:$F$63,B7,'ریز گزارش ارزی'!$G$8:$G$63,C7,'ریز گزارش ارزی'!$AO$8:$AO$63,D7,'ریز گزارش ارزی'!$AP$8:$AP$63,E7) -> 0 | H7: =SUMIFS('ریز گزارش ارزی'!$AD$8:$AD$63,'ریز گزارش ارزی'!$AD$8:$AD$63,">0",'ریز گزارش ارزی'!$AG$8:$AG$63,"قرض",'ریز گزارش ارزی'!$H$8:$H$63,F7,'ریز گزارش ارزی'!$F$8:$F$63,B7,'ریز گزارش ارزی'!$G$8:$G$63,C7,'ریز گزارش ارزی'!$AO$8:$AO$63,D7,'ریز گزارش ارزی'!$AP$8:$AP$63,E7) -> 0 | I7: =SUMIFS('ریز گزارش ارزی'!$AC$8:$AC$63,'ریز گزارش ارزی'!$AC$8:$AC$63,">0",'ریز گزارش ارزی'!$AG$8:$AG$63,"عودت قرض",'ریز گزارش ارزی'!$H$8:$H$63,F7,'ریز گزارش ارزی'!$F$8:$F$63,B7,'ریز گزارش ارزی'!$G$8:$G$63,C7,'ریز گزارش ارزی'!$AO$8:$AO$63,D7,'ریز گزارش ارزی'!$AP$8:$AP$63,E7) -> 0 | J7: =SUMIFS('ریز گزارش ارزی'!$AD$8:$AD$63,'ریز گزارش ارزی'!$AD$8:$AD$63,">0",'ریز گزارش ارزی'!$AG$8:$AG$63,"عودت قرض",'ریز گزارش ارزی'!$H$8:$H$63,F7,'ریز گزارش ارزی'!$F$8:$F$63,B7,'ریز گزارش ارزی'!$G$8:$G$63,C7,'ریز گزارش ارزی'!$AO$8:$AO$63,D7,'ریز گزارش ارزی'!$AP$8:$AP$63,E7) -> 0 | K7: =H7-I7 -> 0 | L7: =G7-J7 -> 0 | M7: =K7-L7 -> 0 | N7: =IF(M7=0,"بی‌حساب",IF(M7>0,"طلبکار","بدهکار")) -> بی‌حساب
B8: Project 1 | C8: تولید | D8: راه اندازی | E8: Project 1 | F8: AED | G8: =SUMIFS('ریز گزارش ارزی'!$AC$8:$AC$63,'ریز گزارش ارزی'!$AC$8:$AC$63,">0",'ریز گزارش ارزی'!$AG$8:$AG$63,"قرض",'ریز گزارش ارزی'!$H$8:$H$63,F8,'ریز گزارش ارزی'!$F$8:$F$63,B8,'ریز گزارش ارزی'!$G$8:$G$63,C8,'ریز گزارش ارزی'!$AO$8:$AO$63,D8,'ریز گزارش ارزی'!$AP$8:$AP$63,E8) -> 0 | H8: =SUMIFS('ریز گزارش ارزی'!$AD$8:$AD$63,'ریز گزارش ارزی'!$AD$8:$AD$63,">0",'ریز گزارش ارزی'!$AG$8:$AG$63,"قرض",'ریز گزارش ارزی'!$H$8:$H$63,F8,'ریز گزارش ارزی'!$F$8:$F$63,B8,'ریز گزارش ارزی'!$G$8:$G$63,C8,'ریز گزارش ارزی'!$AO$8:$AO$63,D8,'ریز گزارش ارزی'!$AP$8:$AP$63,E8) -> 0 | I8: =SUMIFS('ریز گزارش ارزی'!$AC$8:$AC$63,'ریز گزارش ارزی'!$AC$8:$AC$63,">0",'ریز گزارش ارزی'!$AG$8:$AG$63,"عودت قرض",'ریز گزارش ارزی'!$H$8:$H$63,F8,'ریز گزارش ارزی'!$F$8:$F$63,B8,'ریز گزارش ارزی'!$G$8:$G$63,C8,'ریز گزارش ارزی'!$AO$8:$AO$63,D8,'ریز گزارش ارزی'!$AP$8:$AP$63,E8) -> 0 | J8: =SUMIFS('ریز گزارش ارزی'!$AD$8:$AD$63,'ریز گزارش ارزی'!$AD$8:$AD$63,">0",'ریز گزارش ارزی'!$AG$8:$AG$63,"عودت قرض",'ریز گزارش ارزی'!$H$8:$H$63,F8,'ریز گزارش ارزی'!$F$8:$F$63,B8,'ریز گزارش ارزی'!$G$8:$G$63,C8,'ریز گزارش ارزی'!$AO$8:$AO$63,D8,'ریز گزارش ارزی'!$AP$8:$AP$63,E8) -> 0 | K8: =H8-I8 -> 0 | L8: =G8-J8 -> 0 | M8: =K8-L8 -> 0 | N8: =IF(M8=0,"بی‌حساب",IF(M8>0,"طلبکار","بدهکار")) -> بی‌حساب
B9: Project 1 | C9: تولید | D9: مکانیکال | E9: Project 1 | F9: AED | G9: =SUMIFS('ریز گزارش ارزی'!$AC$8:$AC$63,'ریز گزارش ارزی'!$AC$8:$AC$63,">0",'ریز گزارش ارزی'!$AG$8:$AG$63,"قرض",'ریز گزارش ارزی'!$H$8:$H$63,F9,'ریز گزارش ارزی'!$F$8:$F$63,B9,'ریز گزارش ارزی'!$G$8:$G$63,C9,'ریز گزارش ارزی'!$AO$8:$AO$63,D9,'ریز گزارش ارزی'!$AP$8:$AP$63,E9) -> 0 | H9: =SUMIFS('ریز گزارش ارزی'!$AD$8:$AD$63,'ریز گزارش ارزی'!$AD$8:$AD$63,">0",'ریز گزارش ارزی'!$AG$8:$AG$63,"قرض",'ریز گزارش ارزی'!$H$8:$H$63,F9,'ریز گزارش ارزی'!$F$8:$F$63,B9,'ریز گزارش ارزی'!$G$8:$G$63,C9,'ریز گزارش ارزی'!$AO$8:$AO$63,D9,'ریز گزارش ارزی'!$AP$8:$AP$63,E9) -> 14 | I9: =SUMIFS('ریز گزارش ارزی'!$AC$8:$AC$63,'ریز گزارش ارزی'!$AC$8:$AC$63,">0",'ریز گزارش ارزی'!$AG$8:$AG$63,"عودت قرض",'ریز گزارش ارزی'!$H$8:$H$63,F9,'ریز گزارش ارزی'!$F$8:$F$63,B9,'ریز گزارش ارزی'!$G$8:$G$63,C9,'ریز گزارش ارزی'!$AO$8:$AO$63,D9,'ریز گزارش ارزی'!$AP$8:$AP$63,E9) -> 0 | J9: =SUMIFS('ریز گزارش ارزی'!$AD$8:$AD$63,'ریز گزارش ارزی'!$AD$8:$AD$63,">0",'ریز گزارش ارزی'!$AG$8:$AG$63,"عودت قرض",'ریز گزارش ارزی'!$H$8:$H$63,F9,'ریز گزارش ارزی'!$F$8:$F$63,B9,'ریز گزارش ارزی'!$G$8:$G$63,C9,'ریز گزارش ارزی'!$AO$8:$AO$63,D9,'ریز گزارش ارزی'!$AP$8:$AP$63,E9) -> 0 | K9: =H9-I9 -> 14 | L9: =G9-J9 -> 0 | M9: =K9-L9 -> 14 | N9: =IF(M9=0,"بی‌حساب",IF(M9>0,"طلبکار","بدهکار")) -> طلبکار
B10: Project 1 | C10: تولید | D10: مهندسی | E10: Project 1 | F10: AED | G10: =SUMIFS('ریز گزارش ارزی'!$AC$8:$AC$63,'ریز گزارش ارزی'!$AC$8:$AC$63,">0",'ریز گزارش ارزی'!$AG$8:$AG$63,"قرض",'ریز گزارش ارزی'!$H$8:$H$63,F10,'ریز گزارش ارزی'!$F$8:$F$63,B10,'ریز گزارش ارزی'!$G$8:$G$63,C10,'ریز گزارش ارزی'!$AO$8:$AO$63,D10,'ریز گزارش ارزی'!$AP$8:$AP$63,E10) -> 0 | H10: =SUMIFS('ریز گزارش ارزی'!$AD$8:$AD$63,'ریز گزارش ارزی'!$AD$8:$AD$63,">0",'ریز گزارش ارزی'!$AG$8:$AG$63,"قرض",'ریز گزارش ارزی'!$H$8:$H$63,F10,'ریز گزارش ارزی'!$F$8:$F$63,B10,'ریز گزارش ارزی'!$G$8:$G$63,C10,'ریز گزارش ارزی'!$AO$8:$AO$63,D10,'ریز گزارش ارزی'!$AP$8:$AP$63,E10) -> 0 | I10: =SUMIFS('ریز گزارش ارزی'!$AC$8:$AC$63,'ریز گزارش ارزی'!$AC$8:$AC$63,">0",'ریز گزارش ارزی'!$AG$8:$AG$63,"عودت قرض",'ریز گزارش ارزی'!$H$8:$H$63,F10,'ریز گزارش ارزی'!$F$8:$F$63,B10,'ریز گزارش ارزی'!$G$8:$G$63,C10,'ریز گزارش ارزی'!$AO$8:$AO$63,D10,'ریز گزارش ارزی'!$AP$8:$AP$63,E10) -> 0 | J10: =SUMIFS('ریز گزارش ارزی'!$AD$8:$AD$63,'ریز گزارش ارزی'!$AD$8:$AD$63,">0",'ریز گزارش ارزی'!$AG$8:$AG$63,"عودت قرض",'ریز گزارش ارزی'!$H$8:$H$63,F10,'ریز گزارش ارزی'!$F$8:$F$63,B10,'ریز گزارش ارزی'!$G$8:$G$63,C10,'ریز گزارش ارزی'!$AO$8:$AO$63,D10,'ریز گزارش ارزی'!$AP$8:$AP$63,E10) -> 0 | K10: =H10-I10 -> 0 | L10: =G10-J10 -> 0 | M10: =K10-L10 -> 0 | N10: =IF(M10=0,"بی‌حساب",IF(M10>0,"طلبکار","بدهکار")) -> بی‌حساب
B11: Project 1 | C11: تولید | D11: مدیریت | E11: Project 1 | F11: AED | G11: =SUMIFS('ریز گزارش ارزی'!$AC$8:$AC$63,'ریز گزارش ارزی'!$AC$8:$AC$63,">0",'ریز گزارش ارزی'!$AG$8:$AG$63,"قرض",'ریز گزارش ارزی'!$H$8:$H$63,F11,'ریز گزارش ارزی'!$F$8:$F$63,B11,'ریز گزارش ارزی'!$G$8:$G$63,C11,'ریز گزارش ارزی'!$AO$8:$AO$63,D11,'ریز گزارش ارزی'!$AP$8:$AP$63,E11) -> 0 | H11: =SUMIFS('ریز گزارش ارزی'!$AD$8:$AD$63,'ریز گزارش ارزی'!$AD$8:$AD$63,">0",'ریز گزارش ارزی'!$AG$8:$AG$63,"قرض",'ریز گزارش ارزی'!$H$8:$H$63,F11,'ریز گزارش ارزی'!$F$8:$F$63,B11,'ریز گزارش ارزی'!$G$8:$G$63,C11,'ریز گزارش ارزی'!$AO$8:$AO$63,D11,'ریز گزارش ارزی'!$AP$8:$AP$63,E11) -> 0 | I11: =SUMIFS('ریز گزارش ارزی'!$AC$8:$AC$63,'ریز گزارش ارزی'!$AC$8:$AC$63,">0",'ریز گزارش ارزی'!$AG$8:$AG$63,"عودت قرض",'ریز گزارش ارزی'!$H$8:$H$63,F11,'ریز گزارش ارزی'!$F$8:$F$63,B11,'ریز گزارش ارزی'!$G$8:$G$63,C11,'ریز گزارش ارزی'!$AO$8:$AO$63,D11,'ریز گزارش ارزی'!$AP$8:$AP$63,E11) -> 0 | J11: =SUMIFS('ریز گزارش ارزی'!$AD$8:$AD$63,'ریز گزارش ارزی'!$AD$8:$AD$63,">0",'ریز گزارش ارزی'!$AG$8:$AG$63,"عودت قرض",'ریز گزارش ارزی'!$H$8:$H$63,F11,'ریز گزارش ارزی'!$F$8:$F$63,B11,'ریز گزارش ارزی'!$G$8:$G$63,C11,'ریز گزارش ارزی'!$AO$8:$AO$63,D11,'ریز گزارش ارزی'!$AP$8:$AP$63,E11) -> 0 | K11: =H11-I11 -> 0 | L11: =G11-J11 -> 0 | M11: =K11-L11 -> 0 | N11: =IF(M11=0,"بی‌حساب",IF(M11>0,"طلبکار","بدهکار")) -> بی‌حساب
B12: Project 1 | C12: تامین | D12: تولید | E12: Project 1 | F12: AED | G12: =SUMIFS('ریز گزارش ارزی'!$AC$8:$AC$63,'ریز گزارش ارزی'!$AC$8:$AC$63,">0",'ریز گزارش ارزی'!$AG$8:$AG$63,"قرض",'ریز گزارش ارزی'!$H$8:$H$63,F12,'ریز گزارش ارزی'!$F$8:$F$63,B12,'ریز گزارش ارزی'!$G$8:$G$63,C12,'ریز گزارش ارزی'!$AO$8:$AO$63,D12,'ریز گزارش ارزی'!$AP$8:$AP$63,E12) -> 0 | H12: =SUMIFS('ریز گزارش ارزی'!$AD$8:$AD$63,'ریز گزارش ارزی'!$AD$8:$AD$63,">0",'ریز گزارش ارزی'!$AG$8:$AG$63,"قرض",'ریز گزارش ارزی'!$H$8:$H$63,F12,'ریز گزارش ارزی'!$F$8:$F$63,B12,'ریز گزارش ارزی'!$G$8:$G$63,C12,'ریز گزارش ارزی'!$AO$8:$AO$63,D12,'ریز گزارش ارزی'!$AP$8:$AP$63,E12) -> 80 | I12: =SUMIFS('ریز گزارش ارزی'!$AC$8:$AC$63,'ریز گزارش ارزی'!$AC$8:$AC$63,">0",'ریز گزارش ارزی'!$AG$8:$AG$63,"عودت قرض",'ریز گزارش ارزی'!$H$8:$H$63,F12,'ریز گزارش ارزی'!$F$8:$F$63,B12,'ریز گزارش ارزی'!$G$8:$G$63,C12,'ریز گزارش ارزی'!$AO$8:$AO$63,D12,'ریز گزارش ارزی'!$AP$8:$AP$63,E12) -> 0 | J12: =SUMIFS('ریز گزارش ارزی'!$AD$8:$AD$63,'ریز گزارش ارزی'!$AD$8:$AD$63,">0",'ریز گزارش ارزی'!$AG$8:$AG$63,"عودت قرض",'ریز گزارش ارزی'!$H$8:$H$63,F12,'ریز گزارش ارزی'!$F$8:$F$63,B12,'ریز گزارش ارزی'!$G$8:$G$63,C12,'ریز گزارش ارزی'!$AO$8:$AO$63,D12,'ریز گزارش ارزی'!$AP$8:$AP$63,E12) -> 0 | K12: =H12-I12 -> 80 | L12: =G12-J12 -> 0 | M12: =K12-L12 -> 80 | N12: =IF(M12=0,"بی‌حساب",IF(M12>0,"طلبکار","بدهکار")) -> طلبکار
B13: Project 1 | C13: تامین | D13: نصب | E13: Project 1 | F13: AED | G13: =SUMIFS('ریز گزارش ارزی'!$AC$8:$AC$63,'ریز گزارش ارزی'!$AC$8:$AC$63,">0",'ریز گزارش ارزی'!$AG$8:$AG$63,"قرض",'ریز گزارش ارزی'!$H$8:$H$63,F13,'ریز گزارش ارزی'!$F$8:$F$63,B13,'ریز گزارش ارزی'!$G$8:$G$63,C13,'ریز گزارش ارزی'!$AO$8:$AO$63,D13,'ریز گزارش ارزی'!$AP$8:$AP$63,E13) -> 0 | H13: =SUMIFS('ریز گزارش ارزی'!$AD$8:$AD$63,'ریز گزارش ارزی'!$AD$8:$AD$63,">0",'ریز گزارش ارزی'!$AG$8:$AG$63,"قرض",'ریز گزارش ارزی'!$H$8:$H$63,F13,'ریز گزارش ارزی'!$F$8:$F$63,B13,'ریز گزارش ارزی'!$G$8:$G$63,C13,'ریز گزارش ارزی'!$AO$8:$AO$63,D13,'ریز گزارش ارزی'!$AP$8:$AP$63,E13) -> 0 | I13: =SUMIFS('ریز گزارش ارزی'!$AC$8:$AC$63,'ریز گزارش ارزی'!$AC$8:$AC$63,">0",'ریز گزارش ارزی'!$AG$8:$AG$63,"عودت قرض",'ریز گزارش ارزی'!$H$8:$H$63,F13,'ریز گزارش ارزی'!$F$8:$F$63,B13,'ریز گزارش ارزی'!$G$8:$G$63,C13,'ریز گزارش ارزی'!$AO$8:$AO$63,D13,'ریز گزارش ارزی'!$AP$8:$AP$63,E13) -> 0 | J13: =SUMIFS('ریز گزارش ارزی'!$AD$8:$AD$63,'ریز گزارش ارزی'!$AD$8:$AD$63,">0",'ریز گزارش ارزی'!$AG$8:$AG$63,"عودت قرض",'ریز گزارش ارزی'!$H$8:$H$63,F13,'ریز گزارش ارزی'!$F$8:$F$63,B13,'ریز گزارش ارزی'!$G$8:$G$63,C13,'ریز گزارش ارزی'!$AO$8:$AO$63,D13,'ریز گزارش ارزی'!$AP$8:$AP$63,E13) -> 0 | K13: =H13-I13 -> 0 | L13: =G13-J13 -> 0 | M13: =K13-L13 -> 0 | N13: =IF(M13=0,"بی‌حساب",IF(M13>0,"طلبکار","بدهکار")) -> بی‌حساب
B14: Project 1 | C14: تامین | D14: راه اندازی | E14: Project 1 | F14: AED | G14: =SUMIFS('ریز گزارش ارزی'!$AC$8:$AC$63,'ریز گزارش ارزی'!$AC$8:$AC$63,">0",'ریز گزارش ارزی'!$AG$8:$AG$63,"قرض",'ریز گزارش ارزی'!$H$8:$H$63,F14,'ریز گزارش ارزی'!$F$8:$F$63,B14,'ریز گزارش ارزی'!$G$8:$G$63,C14,'ریز گزارش ارزی'!$AO$8:$AO$63,D14,'ریز گزارش ارزی'!$AP$8:$AP$63,E14) -> 0 | H14: =SUMIFS('ریز گزارش ارزی'!$AD$8:$AD$63,'ریز گزارش ارزی'!$AD$8:$AD$63,">0",'ریز گزارش ارزی'!$AG$8:$AG$63,"قرض",'ریز گزارش ارزی'!$H$8:$H$63,F14,'ریز گزارش ارزی'!$F$8:$F$63,B14,'ریز گزارش ارزی'!$G$8:$G$63,C14,'ریز گزارش ارزی'!$AO$8:$AO$63,D14,'ریز گزارش ارزی'!$AP$8:$AP$63,E14) -> 0 | I14: =SUMIFS('ریز گزارش ارزی'!$AC$8:$AC$63,'ریز گزارش ارزی'!$AC$8:$AC$63,">0",'ریز گزارش ارزی'!$AG$8:$AG$63,"عودت قرض",'ریز گزارش ارزی'!$H$8:$H$63,F14,'ریز گزارش ارزی'!$F$8:$F$63,B14,'ریز گزارش ارزی'!$G$8:$G$63,C14,'ریز گزارش ارزی'!$AO$8:$AO$63,D14,'ریز گزارش ارزی'!$AP$8:$AP$63,E14) -> 0 | J14: =SUMIFS('ریز گزارش ارزی'!$AD$8:$AD$63,'ریز گزارش ارزی'!$AD$8:$AD$63,">0",'ریز گزارش ارزی'!$AG$8:$AG$63,"عودت قرض",'ریز گزارش ارزی'!$H$8:$H$63,F14,'ریز گزارش ارزی'!$F$8:$F$63,B14,'ریز گزارش ارزی'!$G$8:$G$63,C14,'ریز گزارش ارزی'!$AO$8:$AO$63,D14,'ریز گزارش ارزی'!$AP$8:$AP$63,E14) -> 0 | K14: =H14-I14 -> 0 | L14: =G14-J14 -> 0 | M14: =K14-L14 -> 0 | N14: =IF(M14=0,"بی‌حساب",IF(M14>0,"طلبکار","بدهکار")) -> بی‌حساب
B15: Project 1 | C15: تامین | D15: مکانیکال | E15: Project 1 | F15: AED | G15: =SUMIFS('ریز گزارش ارزی'!$AC$8:$AC$63,'ریز گزارش ارزی'!$AC$8:$AC$63,">0",'ریز گزارش ارزی'!$AG$8:$AG$63,"قرض",'ریز گزارش ارزی'!$H$8:$H$63,F15,'ریز گزارش ارزی'!$F$8:$F$63,B15,'ریز گزارش ارزی'!$G$8:$G$63,C15,'ریز گزارش ارزی'!$AO$8:$AO$63,D15,'ریز گزارش ارزی'!$AP$8:$AP$63,E15) -> 105 | H15: =SUMIFS('ریز گزارش ارزی'!$AD$8:$AD$63,'ریز گزارش ارزی'!$AD$8:$AD$63,">0",'ریز گزارش ارزی'!$AG$8:$AG$63,"قرض",'ریز گزارش ارزی'!$H$8:$H$63,F15,'ریز گزارش ارزی'!$F$8:$F$63,B15,'ریز گزارش ارزی'!$G$8:$G$63,C15,'ریز گزارش ارزی'!$AO$8:$AO$63,D15,'ریز گزارش ارزی'!$AP$8:$AP$63,E15) -> 0 | I15: =SUMIFS('ریز گزارش ارزی'!$AC$8:$AC$63,'ریز گزارش ارزی'!$AC$8:$AC$63,">0",'ریز گزارش ارزی'!$AG$8:$AG$63,"عودت قرض",'ریز گزارش ارزی'!$H$8:$H$63,F15,'ریز گزارش ارزی'!$F$8:$F$63,B15,'ریز گزارش ارزی'!$G$8:$G$63,C15,'ریز گزارش ارزی'!$AO$8:$AO$63,D15,'ریز گزارش ارزی'!$AP$8:$AP$63,E15) -> 0 | J15: =SUMIFS('ریز گزارش ارزی'!$AD$8:$AD$63,'ریز گزارش ارزی'!$AD$8:$AD$63,">0",'ریز گزارش ارزی'!$AG$8:$AG$63,"عودت قرض",'ریز گزارش ارزی'!$H$8:$H$63,F15,'ریز گزارش ارزی'!$F$8:$F$63,B15,'ریز گزارش ارزی'!$G$8:$G$63,C15,'ریز گزارش ارزی'!$AO$8:$AO$63,D15,'ریز گزارش ارزی'!$AP$8:$AP$63,E15) -> 68 | K15: =H15-I15 -> 0 | L15: =G15-J15 -> 37 | M15: =K15-L15 -> -37 | N15: =IF(M15=0,"بی‌حساب",IF(M15>0,"طلبکار","بدهکار")) -> بدهکار
B16: Project 1 | C16: تامین | D16: مهندسی | E16: Project 1 | F16: AED | G16: =SUMIFS('ریز گزارش ارزی'!$AC$8:$AC$63,'ریز گزارش ارزی'!$AC$8:$AC$63,">0",'ریز گزارش ارزی'!$AG$8:$AG$63,"قرض",'ریز گزارش ارزی'!$H$8:$H$63,F16,'ریز گزارش ارزی'!$F$8:$F$63,B16,'ریز گزارش ارزی'!$G$8:$G$63,C16,'ریز گزارش ارزی'!$AO$8:$AO$63,D16,'ریز گزارش ارزی'!$AP$8:$AP$63,E16) -> 14 | H16: =SUMIFS('ریز گزارش ارزی'!$AD$8:$AD$63,'ریز گزارش ارزی'!$AD$8:$AD$63,">0",'ریز گزارش ارزی'!$AG$8:$AG$63,"قرض",'ریز گزارش ارزی'!$H$8:$H$63,F16,'ریز گزارش ارزی'!$F$8:$F$63,B16,'ریز گزارش ارزی'!$G$8:$G$63,C16,'ریز گزارش ارزی'!$AO$8:$AO$63,D16,'ریز گزارش ارزی'!$AP$8:$AP$63,E16) -> 0 | I16: =SUMIFS('ریز گزارش ارزی'!$AC$8:$AC$63,'ریز گزارش ارزی'!$AC$8:$AC$63,">0",'ریز گزارش ارزی'!$AG$8:$AG$63,"عودت قرض",'ریز گزارش ارزی'!$H$8:$H$63,F16,'ریز گزارش ارزی'!$F$8:$F$63,B16,'ریز گزارش ارزی'!$G$8:$G$63,C16,'ریز گزارش ارزی'!$AO$8:$AO$63,D16,'ریز گزارش ارزی'!$AP$8:$AP$63,E16) -> 0 | J16: =SUMIFS('ریز گزارش ارزی'!$AD$8:$AD$63,'ریز گزارش ارزی'!$AD$8:$AD$63,">0",'ریز گزارش ارزی'!$AG$8:$AG$63,"عودت قرض",'ریز گزارش ارزی'!$H$8:$H$63,F16,'ریز گزارش ارزی'!$F$8:$F$63,B16,'ریز گزارش ارزی'!$G$8:$G$63,C16,'ریز گزارش ارزی'!$AO$8:$AO$63,D16,'ریز گزارش ارزی'!$AP$8:$AP$63,E16) -> 0 | K16: =H16-I16 -> 0 | L16: =G16-J16 -> 14 | M16: =K16-L16 -> -14 | N16: =IF(M16=0,"بی‌حساب",IF(M16>0,"طلبکار","بدهکار")) -> بدهکار
B17: Project 1 | C17: تامین | D17: مدیریت | E17: Project 1 | F17: AED | G17: =SUMIFS('ریز گزارش ارزی'!$AC$8:$AC$63,'ریز گزارش ارزی'!$AC$8:$AC$63,">0",'ریز گزارش ارزی'!$AG$8:$AG$63,"قرض",'ریز گزارش ارزی'!$H$8:$H$63,F17,'ریز گزارش ارزی'!$F$8:$F$63,B17,'ریز گزارش ارزی'!$G$8:$G$63,C17,'ریز گزارش ارزی'!$AO$8:$AO$63,D17,'ریز گزارش ارزی'!$AP$8:$AP$63,E17) -> 0 | H17: =SUMIFS('ریز گزارش ارزی'!$AD$8:$AD$63,'ریز گزارش ارزی'!$AD$8:$AD$63,">0",'ریز گزارش ارزی'!$AG$8:$AG$63,"قرض",'ریز گزارش ارزی'!$H$8:$H$63,F17,'ریز گزارش ارزی'!$F$8:$F$63,B17,'ریز گزارش ارزی'!$G$8:$G$63,C17,'ریز گزارش ارزی'!$AO$8:$AO$63,D17,'ریز گزارش ارزی'!$AP$8:$AP$63,E17) -> 0 | I17: =SUMIFS('ریز گزارش ارزی'!$AC$8:$AC$63,'ریز گزارش ارزی'!$AC$8:$AC$63,">0",'ریز گزارش ارزی'!$AG$8:$AG$63,"عودت قرض",'ریز گزارش ارزی'!$H$8:$H$63,F17,'ریز گزارش ارزی'!$F$8:$F$63,B17,'ریز گزارش ارزی'!$G$8:$G$63,C17,'ریز گزارش ارزی'!$AO$8:$AO$63,D17,'ریز گزارش ارزی'!$AP$8:$AP$63,E17) -> 0 | J17: =SUMIFS('ریز گزارش ارزی'!$AD$8:$AD$63,'ریز گزارش ارزی'!$AD$8:$AD$63,">0",'ریز گزارش ارزی'!$AG$8:$AG$63,"عودت قرض",'ریز گزارش ارزی'!$H$8:$H$63,F17,'ریز گزارش ارزی'!$F$8:$F$63,B17,'ریز گزارش ارزی'!$G$8:$G$63,C17,'ریز گزارش ارزی'!$AO$8:$AO$63,D17,'ریز گزارش ارزی'!$AP$8:$AP$63,E17) -> 0 | K17: =H17-I17 -> 0 | L17: =G17-J17 -> 0 | M17: =K17-L17 -> 0 | N17: =IF(M17=0,"بی‌حساب",IF(M17>0,"طلبکار","بدهکار")) -> بی‌حساب
... B187: Project 2 | C187: مدیریت | D187: مدیریت | E187: Project 1 | F187: AED | G187: =SUMIFS('ریز گزارش ارزی'!$AC$8:$AC$63,'ریز گزارش ارزی'!$AC$8:$AC$63,">0",'ریز گزارش ارزی'!$AG$8:$AG$63,"قرض",'ریز گزارش ارزی'!$H$8:$H$63,F187,'ریز گزارش ارزی'!$F$8:$F$63,B187,'ریز گزارش ارزی'!$G$8:$G$63,C187,'ریز گزارش ارزی'!$AO$8:$AO$63,D187,'ریز گزارش ارزی'!$AP$8:$AP$63,E187) -> 0 | H187: =SUMIFS('ریز گزارش ارزی'!$AD$8:$AD$63,'ریز گزارش ارزی'!$AD$8:$AD$63,">0",'ریز گزارش ارزی'!$AG$8:$AG$63,"قرض",'ریز گزارش ارزی'!$H$8:$H$63,F187,'ریز گزارش ارزی'!$F$8:$F$63,B187,'ریز گزارش ارزی'!$G$8:$G$63,C187,'ریز گزارش ارزی'!$AO$8:$AO$63,D187,'ریز گزارش ارزی'!$AP$8:$AP$63,E187) -> 0 | I187: =SUMIFS('ریز گزارش ارزی'!$AC$8:$AC$63,'ریز گزارش ارزی'!$AC$8:$AC$63,">0",'ریز گزارش ارزی'!$AG$8:$AG$63,"عودت قرض",'ریز گزارش ارزی'!$H$8:$H$63,F187,'ریز گزارش ارزی'!$F$8:$F$63,B187,'ریز گزارش ارزی'!$G$8:$G$63,C187,'ریز گزارش ارزی'!$AO$8:$AO$63,D187,'ریز گزارش ارزی'!$AP$8:$AP$63,E187) -> 0 | J187: =SUMIFS('ریز گزارش ارزی'!$AD$8:$AD$63,'ریز گزارش ارزی'!$AD$8:$AD$63,">0",'ریز گزارش ارزی'!$AG$8:$AG$63,"عودت قرض",'ریز گزارش ارزی'!$H$8:$H$63,F187,'ریز گزارش ارزی'!$F$8:$F$63,B187,'ریز گزارش ارزی'!$G$8:$G$63,C187,'ریز گزارش ارزی'!$AO$8:$AO$63,D187,'ریز گزارش ارزی'!$AP$8:$AP$63,E187) -> 0 | K187: =H187-I187 -> 0 | L187: =G187-J187 -> 0 | M187: =K187-L187 -> 0 | N187: =IF(M187=0,"بی‌حساب",IF(M187>0,"طلبکار","بدهکار")) -> بی‌حساب
F188: جمع | G188: =SUM(G6:G187) -> 406 | H188: =SUM(H6:H187) -> 406 | I188: =SUM(I6:I187) -> 68 | J188: =SUM(J6:J187) -> 68 | K188: =SUM(K6:K187) -> 338 | L188: =SUM(L6:L187) -> 338 | M188: =SUM(M6:M187) -> 0

Sheet ریز نقدینگی ارزی
B3: ارز | C3: کد پروژه کارفرما | D3: شرح | E3: واکا (SBU) | F3: بدهکار | G3: بستانکار | I3: ارز | J3: کد پروژه کارفرما | K3: شرح | L3: واکا (SBU) | M3: بدهکار | N3: بستانکار
B4: € | C4: Project 1 | D4: پروژه/پرداخت | E4: تولید | F4: =SUMIFS('ریز گزارش ارزی'!$AC$8:$AC$9818,'ریز گزارش ارزی'!$AC$8:$AC$9818,">0",'ریز گزارش ارزی'!$AF$8:$AF$9818,"1",'ریز گزارش ارزی'!$H$8:$H$9818,B4,'ریز گزارش ارزی'!$F$8:$F$9818,C4,'ریز گزارش ارزی'!$G$8:$G$9818,E4) -> 13 | G4: =SUMIFS('ریز گزارش ارزی'!$AD$8:$AD$9818,'ریز گزارش ارزی'!$AD$8:$AD$9818,">0",'ریز گزارش ارزی'!$AF$8:$AF$9818,"2",'ریز گزارش ارزی'!$H$8:$H$9818,B4,'ریز گزارش ارزی'!$F$8:$F$9818,C4,'ریز گزارش ارزی'!$G$8:$G$9818,E4) -> 13 | I4: € | J4: Project 1 | K4: دریافتی از کارفرما | L4: تولید | M4: =SUMIFS('ریز گزارش ارزی'!$L$8:$L$9818,'ریز گزارش ارزی'!$L$8:$L$9818,">0",'ریز گزارش ارزی'!$H$8:$H$9818,I4,'ریز گزارش ارزی'!$F$8:$F$9818,J4,'ریز گزارش ارزی'!$G$8:$G$9818,L4) -> 0
B5: € | C5: Project 1 | D5: پروژه/پرداخت | E5: تامین | F5: =SUMIFS('ریز گزارش ارزی'!$AC$8:$AC$9818,'ریز گزارش ارزی'!$AC$8:$AC$9818,">0",'ریز گزارش ارزی'!$AF$8:$AF$9818,"1",'ریز گزارش ارزی'!$H$8:$H$9818,B5,'ریز گزارش ارزی'!$F$8:$F$9818,C5,'ریز گزارش ارزی'!$G$8:$G$9818,E5) -> 453.27 | G5: =SUMIFS('ریز گزارش ارزی'!$AD$8:$AD$9818,'ریز گزارش ارزی'!$AD$8:$AD$9818,">0",'ریز گزارش ارزی'!$AF$8:$AF$9818,"2",'ریز گزارش ارزی'!$H$8:$H$9818,B5,'ریز گزارش ارزی'!$F$8:$F$9818,C5,'ریز گزارش ارزی'!$G$8:$G$9818,E5) -> 18 | I5: € | J5: Project 1 | K5: دریافتی از کارفرما | L5: تامین | M5: =SUMIFS('ریز گزارش ارزی'!$L$8:$L$9818,'ریز گزارش ارزی'!$L$8:$L$9818,">0",'ریز گزارش ارزی'!$H$8:$H$9818,I5,'ریز گزارش ارزی'!$F$8:$F$9818,J5,'ریز گزارش ارزی'!$G$8:$G$9818,L5) -> 521
B6: € | C6: Project 1 | D6: پروژه/پرداخت | E6: نصب | F6: =SUMIFS('ریز گزارش ارزی'!$AC$8:$AC$9818,'ریز گزارش ارزی'!$AC$8:$AC$9818,">0",'ریز گزارش ارزی'!$AF$8:$AF$9818,"1",'ریز گزارش ارزی'!$H$8:$H$9818,B6,'ریز گزارش ارزی'!$F$8:$F$9818,C6,'ریز گزارش ارزی'!$G$8:$G$9818,E6) -> 0 | G6: =SUMIFS('ریز گزارش ارزی'!$AD$8:$AD$9818,'ریز گزارش ارزی'!$AD$8:$AD$9818,">0",'ریز گزارش ارزی'!$AF$8:$AF$9818,"2",'ریز گزارش ارزی'!$H$8:$H$9818,B6,'ریز گزارش ارزی'!$F$8:$F$9818,C6,'ریز گزارش ارزی'!$G$8:$G$9818,E6) -> 0 | I6: € | J6: Project 1 | K6: دریافتی از کارفرما | L6: نصب | M6: =SUMIFS('ریز گزارش ارزی'!$L$8:$L$9818,'ریز گزارش ارزی'!$L$8:$L$9818,">0",'ریز گزارش ارزی'!$H$8:$H$9818,I6,'ریز گزارش ارزی'!$F$8:$F$9818,J6,'ریز گزارش ارزی'!$G$8:$G$9818,L6) -> 0
B7: € | C7: Project 1 | D7: پروژه/پرداخت | E7: راه اندازی | F7: =SUMIFS('ریز گزارش ارزی'!$AC$8:$AC$9818,'ریز گزارش ارزی'!$AC$8:$AC$9818,">0",'ریز گزارش ارزی'!$AF$8:$AF$9818,"1",'ریز گزارش ارزی'!$H$8:$H$9818,B7,'ریز گزارش ارزی'!$F$8:$F$9818,C7,'ریز گزارش ارزی'!$G$8:$G$9818,E7) -> 0 | G7: =SUMIFS('ریز گزارش ارزی'!$AD$8:$AD$9818,'ریز گزارش ارزی'!$AD$8:$AD$9818,">0",'ریز گزارش ارزی'!$AF$8:$AF$9818,"2",'ریز گزارش ارزی'!$H$8:$H$9818,B7,'ریز گزارش ارزی'!$F$8:$F$9818,C7,'ریز گزارش ارزی'!$G$8:$G$9818,E7) -> 0 | I7: € | J7: Project 1 | K7: دریافتی از کارفرما | L7: راه اندازی | M7: =SUMIFS('ریز گزارش ارزی'!$L$8:$L$9818,'ریز گزارش ارزی'!$L$8:$L$9818,">0",'ریز گزارش ارزی'!$H$8:$H$9818,I7,'ریز گزارش ارزی'!$F$8:$F$9818,J7,'ریز گزارش ارزی'!$G$8:$G$9818,L7) -> 0
B8: € | C8: Project 1 | D8: پروژه/پرداخت | E8: مکانیکال | F8: =SUMIFS('ریز گزارش ارزی'!$AC$8:$AC$9818,'ریز گزارش ارزی'!$AC$8:$AC$9818,">0",'ریز گزارش ارزی'!$AF$8:$AF$9818,"1",'ریز گزارش ارزی'!$H$8:$H$9818,B8,'ریز گزارش ارزی'!$F$8:$F$9818,C8,'ریز گزارش ارزی'!$G$8:$G$9818,E8) -> 0 | G8: =SUMIFS('ریز گزارش ارزی'!$AD$8:$AD$9818,'ریز گزارش ارزی'!$AD$8:$AD$9818,">0",'ریز گزارش ارزی'!$AF$8:$AF$9818,"2",'ریز گزارش ارزی'!$H$8:$H$9818,B8,'ریز گزارش ارزی'!$F$8:$F$9818,C8,'ریز گزارش ارزی'!$G$8:$G$9818,E8) -> 0 | I8: € | J8: Project 1 | K8: دریافتی از کارفرما | L8: مکانیکال | M8: =SUMIFS('ریز گزارش ارزی'!$L$8:$L$9818,'ریز گزارش ارزی'!$L$8:$L$9818,">0",'ریز گزارش ارزی'!$H$8:$H$9818,I8,'ریز گزارش ارزی'!$F$8:$F$9818,J8,'ریز گزارش ارزی'!$G$8:$G$9818,L8) -> 0
B9: € | C9: Project 1 | D9: پروژه/پرداخت | E9: مهندسی | F9: =SUMIFS('ریز گزارش ارزی'!$AC$8:$AC$9818,'ریز گزارش ارزی'!$AC$8:$AC$9818,">0",'ریز گزارش ارزی'!$AF$8:$AF$9818,"1",'ریز گزارش ارزی'!$H$8:$H$9818,B9,'ریز گزارش ارزی'!$F$8:$F$9818,C9,'ریز گزارش ارزی'!$G$8:$G$9818,E9) -> 600 | G9: =SUMIFS('ریز گزارش ارزی'!$AD$8:$AD$9818,'ریز گزارش ارزی'!$AD$8:$AD$9818,">0",'ریز گزارش ارزی'!$AF$8:$AF$9818,"2",'ریز گزارش ارزی'!$H$8:$H$9818,B9,'ریز گزارش ارزی'!$F$8:$F$9818,C9,'ریز گزارش ارزی'!$G$8:$G$9818,E9) -> 23 | I9: € | J9: Project 1 | K9: دریافتی از کارفرما | L9: مهندسی | M9: =SUMIFS('ریز گزارش ارزی'!$L$8:$L$9818,'ریز گزارش ارزی'!$L$8:$L$9818,">0",'ریز گزارش ارزی'!$H$8:$H$9818,I9,'ریز گزارش ارزی'!$F$8:$F$9818,J9,'ریز گزارش ارزی'!$G$8:$G$9818,L9) -> 600
B10: € | C10: Project 1 | D10: پروژه/پرداخت | E10: مدیریت | F10: =SUMIFS('ریز گزارش ارزی'!$AC$8:$AC$9818,'ریز گزارش ارزی'!$AC$8:$AC$9818,">0",'ریز گزارش ارزی'!$AF$8:$AF$9818,"1",'ریز گزارش ارزی'!$H$8:$H$9818,B10,'ریز گزارش ارزی'!$F$8:$F$9818,C10,'ریز گزارش ارزی'!$G$8:$G$9818,E10) -> 0 | G10: =SUMIFS('ریز گزارش ارزی'!$AD$8:$AD$9818,'ریز گزارش ارزی'!$AD$8:$AD$9818,">0",'ریز گزارش ارزی'!$AF$8:$AF$9818,"2",'ریز گزارش ارزی'!$H$8:$H$9818,B10,'ریز گزارش ارزی'!$F$8:$F$9818,C10,'ریز گزارش ارزی'!$G$8:$G$9818,E10) -> 0 | I10: € | J10: Project 1 | K10: دریافتی از کارفرما | L10: مدیریت | M10: =SUMIFS('ریز گزارش ارزی'!$L$8:$L$9818,'ریز گزارش ارزی'!$L$8:$L$9818,">0",'ریز گزارش ارزی'!$H$8:$H$9818,I10,'ریز گزارش ارزی'!$F$8:$F$9818,J10,'ریز گزارش ارزی'!$G$8:$G$9818,L10) -> 0
B11: AED | C11: Project 1 | D11: پروژه/پرداخت | E11: تولید | F11: =SUMIFS('ریز گزارش ارزی'!$AC$8:$AC$9818,'ریز گزارش ارزی'!$AC$8:$AC$9818,">0",'ریز گزارش ارزی'!$AF$8:$AF$9818,"1",'ریز گزارش ارزی'!$H$8:$H$9818,B11,'ریز گزارش ارزی'!$F$8:$F$9818,C11,'ریز گزارش ارزی'!$G$8:$G$9818,E11) -> 0 | G11: =SUMIFS('ریز گزارش ارزی'!$AD$8:$AD$9818,'ریز گزارش ارزی'!$AD$8:$AD$9818,">0",'ریز گزارش ارزی'!$AF$8:$AF$9818,"2",'ریز گزارش ارزی'!$H$8:$H$9818,B11,'ریز گزارش ارزی'!$F$8:$F$9818,C11,'ریز گزارش ارزی'!$G$8:$G$9818,E11) -> 72 | I11: AED | J11: Project 1 | K11: دریافتی از کارفرما | L11: تولید | M11: =SUMIFS('ریز گزارش ارزی'!$L$8:$L$9818,'ریز گزارش ارزی'!$L$8:$L$9818,">0",'ریز گزارش ارزی'!$H$8:$H$9818,I11,'ریز گزارش ارزی'!$F$8:$F$9818,J11,'ریز گزارش ارزی'!$G$8:$G$9818,L11) -> 0
B12: AED | C12: Project 1 | D12: پروژه/پرداخت | E12: تامین | F12: =SUMIFS('ریز گزارش ارزی'!$AC$8:$AC$9818,'ریز گزارش ارزی'!$AC$8:$AC$9818,">0",'ریز گزارش ارزی'!$AF$8:$AF$9818,"1",'ریز گزارش ارزی'!$H$8:$H$9818,B12,'ریز گزارش ارزی'!$F$8:$F$9818,C12,'ریز گزارش ارزی'!$G$8:$G$9818,E12) -> 765.6 | G12: =SUMIFS('ریز گزارش ارزی'!$AD$8:$AD$9818,'ریز گزارش ارزی'!$AD$8:$AD$9818,">0",'ریز گزارش ارزی'!$AF$8:$AF$9818,"2",'ریز گزارش ارزی'!$H$8:$H$9818,B12,'ریز گزارش ارزی'!$F$8:$F$9818,C12,'ریز گزارش ارزی'!$G$8:$G$9818,E12) -> 301 | I12: AED | J12: Project 1 | K12: دریافتی از کارفرما | L12: تامین | M12: =SUMIFS('ریز گزارش ارزی'!$L$8:$L$9818,'ریز گزارش ارزی'!$L$8:$L$9818,">0",'ریز گزارش ارزی'!$H$8:$H$9818,I12,'ریز گزارش ارزی'!$F$8:$F$9818,J12,'ریز گزارش ارزی'!$G$8:$G$9818,L12) -> 870
B13: AED | C13: Project 1 | D13: پروژه/پرداخت | E13: نصب | F13: =SUMIFS('ریز گزارش ارزی'!$AC$8:$AC$9818,'ریز گزارش ارزی'!$AC$8:$AC$9818,">0",'ریز گزارش ارزی'!$AF$8:$AF$9818,"1",'ریز گزارش ارزی'!$H$8:$H$9818,B13,'ریز گزارش ارزی'!$F$8:$F$9818,C13,'ریز گزارش ارزی'!$G$8:$G$9818,E13) -> 0 | G13: =SUMIFS('ریز گزارش ارزی'!$AD$8:$AD$9818,'ریز گزارش ارزی'!$AD$8:$AD$9818,">0",'ریز گزارش ارزی'!$AF$8:$AF$9818,"2",'ریز گزارش ارزی'!$H$8:$H$9818,B13,'ریز گزارش ارزی'!$F$8:$F$9818,C13,'ریز گزارش ارزی'!$G$8:$G$9818,E13) -> 0 | I13: AED | J13: Project 1 | K13: دریافتی از کارفرما | L13: نصب | M13: =SUMIFS('ریز گزارش ارزی'!$L$8:$L$9818,'ریز گزارش ارزی'!$L$8:$L$9818,">0",'ریز گزارش ارزی'!$H$8:$H$9818,I13,'ریز گزارش ارزی'!$F$8:$F$9818,J13,'ریز گزارش ارزی'!$G$8:$G$9818,L13) -> 0
B14: AED | C14: Project 1 | D14: پروژه/پرداخت | E14: راه اندازی | F14: =SUMIFS('ریز گزارش ارزی'!$AC$8:$AC$9818,'ریز گزارش ارزی'!$AC$8:$AC$9818,">0",'ریز گزارش ارزی'!$AF$8:$AF$9818,"1",'ریز گزارش ارزی'!$H$8:$H$9818,B14,'ریز گزارش ارزی'!$F$8:$F$9818,C14,'ریز گزارش ارزی'!$G$8:$G$9818,E14) -> 0 | G14: =SUMIFS('ریز گزارش ارزی'!$AD$8:$AD$9818,'ریز گزارش ارزی'!$AD$8:$AD$9818,">0",'ریز گزارش ارزی'!$AF$8:$AF$9818,"2",'ریز گزارش ارزی'!$H$8:$H$9818,B14,'ریز گزارش ارزی'!$F$8:$F$9818,C14,'ریز گزارش ارزی'!$G$8:$G$9818,E14) -> 0 | I14: AED | J14: Project 1 | K14: دریافتی از کارفرما | L14: راه اندازی | M14: =SUMIFS('ریز گزارش ارزی'!$L$8:$L$9818,'ریز گزارش ارزی'!$L$8:$L$9818,">0",'ریز گزارش ارزی'!$H$8:$H$9818,I14,'ریز گزارش ارزی'!$F$8:$F$9818,J14,'ریز گزارش ارزی'!$G$8:$G$9818,L14) -> 0
B15: AED | C15: Project 1 | D15: پروژه/پرداخت | E15: مکانیکال | F15: =SUMIFS('ریز گزارش ارزی'!$AC$8:$AC$9818,'ریز گزارش ارزی'!$AC$8:$AC$9818,">0",'ریز گزارش ارزی'!$AF$8:$AF$9818,"1",'ریز گزارش ارزی'!$H$8:$H$9818,B15,'ریز گزارش ارزی'!$F$8:$F$9818,C15,'ریز گزارش ارزی'!$G$8:$G$9818,E15) -> 272.2 | G15: =SUMIFS('ریز گزارش ارزی'!$AD$8:$AD$9818,'ریز گزارش ارزی'!$AD$8:$AD$9818,">0",'ریز گزارش ارزی'!$AF$8:$AF$9818,"2",'ریز گزارش ارزی'!$H$8:$H$9818,B15,'ریز گزارش ارزی'!$F$8:$F$9818,C15,'ریز گزارش ارزی'!$G$8:$G$9818,E15) -> 74 | I15: AED | J15: Project 1 | K15: دریافتی از کارفرما | L15: مکانیکال | M15: =SUMIFS('ریز گزارش ارزی'!$L$8:$L$9818,'ریز گزارش ارزی'!$L$8:$L$9818,">0",'ریز گزارش ارزی'!$H$8:$H$9818,I15,'ریز گزارش ارزی'!$F$8:$F$9818,J15,'ریز گزارش ارزی'!$G$8:$G$9818,L15) -> 290
... B31: ¥ | C31: Project 1 | D31: پروژه/پرداخت | E31: مدیریت | F31: =SUMIFS('ریز گزارش ارزی'!$AC$8:$AC$9818,'ریز گزارش ارزی'!$AC$8:$AC$9818,">0",'ریز گزارش ارزی'!$AF$8:$AF$9818,"1",'ریز گزارش ارزی'!$H$8:$H$9818,B31,'ریز گزارش ارزی'!$F$8:$F$9818,C31,'ریز گزارش ارزی'!$G$8:$G$9818,E31) -> 0 | G31: =SUMIFS('ریز گزارش ارزی'!$AD$8:$AD$9818,'ریز گزارش ارزی'!$AD$8:$AD$9818,">0",'ریز گزارش ارزی'!$AF$8:$AF$9818,"2",'ریز گزارش ارزی'!$H$8:$H$9818,B31,'ریز گزارش ارزی'!$F$8:$F$9818,C31,'ریز گزارش ارزی'!$G$8:$G$9818,E31) -> 0 | I31: ¥ | J31: Project 1 | K31: دریافتی از کارفرما | L31: مدیریت | M31: =SUMIFS('ریز گزارش ارزی'!$L$8:$L$9818,'ریز گزارش ارزی'!$L$8:$L$9818,">0",'ریز گزارش ارزی'!$H$8:$H$9818,I31,'ریز گزارش ارزی'!$F$8:$F$9818,J31,'ریز گزارش ارزی'!$G$8:$G$9818,L31) -> 0
B32: € | C32: Project 1 | D32: قرض | E32: تولید | F32: =SUMIFS('ریز گزارش ارزی'!$AC$8:$AC$9818,'ریز گزارش ارزی'!$AC$8:$AC$9818,">0",'ریز گزارش ارزی'!$AF$8:$AF$9818,"4",'ریز گزارش ارزی'!$H$8:$H$9818,B32,'ریز گزارش ارزی'!$F$8:$F$9818,C32,'ریز گزارش ارزی'!$G$8:$G$9818,E32) -> 0 | G32: =SUMIFS('ریز گزارش ارزی'!$AD$8:$AD$9818,'ریز گزارش ارزی'!$AD$8:$AD$9818,">0",'ریز گزارش ارزی'!$AF$8:$AF$9818,"4",'ریز گزارش ارزی'!$H$8:$H$9818,B32,'ریز گزارش ارزی'!$F$8:$F$9818,C32,'ریز گزارش ارزی'!$G$8:$G$9818,E32) -> 0 | I32: € | J32: Project 2 | K32: دریافتی از کارفرما | L32: تولید | M32: =SUMIFS('ریز گزارش ارزی'!$L$8:$L$9818,'ریز گزارش ارزی'!$L$8:$L$9818,">0",'ریز گزارش ارزی'!$H$8:$H$9818,I32,'ریز گزارش ارزی'!$F$8:$F$9818,J32,'ریز گزارش ارزی'!$G$8:$G$9818,L32) -> 0
B33: € | C33: Project 1 | D33: قرض | E33: تامین | F33: =SUMIFS('ریز گزارش ارزی'!$AC$8:$AC$9818,'ریز گزارش ارزی'!$AC$8:$AC$9818,">0",'ریز گزارش ارزی'!$AF$8:$AF$9818,"4",'ریز گزارش ارزی'!$H$8:$H$9818,B33,'ریز گزارش ارزی'!$F$8:$F$9818,C33,'ریز گزارش ارزی'!$G$8:$G$9818,E33) -> 0 | G33: =SUMIFS('ریز گزارش ارزی'!$AD$8:$AD$9818,'ریز گزارش ارزی'!$AD$8:$AD$9818,">0",'ریز گزارش ارزی'!$AF$8:$AF$9818,"4",'ریز گزارش ارزی'!$H$8:$H$9818,B33,'ریز گزارش ارزی'!$F$8:$F$9818,C33,'ریز گزارش ارزی'!$G$8:$G$9818,E33) -> 0 | I33: € | J33: Project 2 | K33: دریافتی از کارفرما | L33: تامین | M33: =SUMIFS('ریز گزارش ارزی'!$L$8:$L$9818,'ریز گزارش ارزی'!$L$8:$L$9818,">0",'ریز گزارش ارزی'!$H$8:$H$9818,I33,'ریز گزارش ارزی'!$F$8:$F$9818,J33,'ریز گزارش ارزی'!$G$8:$G$9818,L33) -> 0
B34: € | C34: Project 1 | D34: قرض | E34: نصب | F34: =SUMIFS('ریز گزارش ارزی'!$AC$8:$AC$9818,'ریز گزارش ارزی'!$AC$8:$AC$9818,">0",'ریز گزارش ارزی'!$AF$8:$AF$9818,"4",'ریز گزارش ارزی'!$H$8:$H$9818,B34,'ریز گزارش ارزی'!$F$8:$F$9818,C34,'ریز گزارش ارزی'!$G$8:$G$9818,E34) -> 0 | G34: =SUMIFS('ریز گزارش ارزی'!$AD$8:$AD$9818,'ریز گزارش ارزی'!$AD$8:$AD$9818,">0",'ریز گزارش ارزی'!$AF$8:$AF$9818,"4",'ریز گزارش ارزی'!$H$8:$H$9818,B34,'ریز گزارش ارزی'!$F$8:$F$9818,C34,'ریز گزارش ارزی'!$G$8:$G$9818,E34) -> 0 | I34: € | J34: Project 2 | K34: دریافتی از کارفرما | L34: نصب | M34: =SUMIFS('ریز گزارش ارزی'!$L$8:$L$9818,'ریز گزارش ارزی'!$L$8:$L$9818,">0",'ریز گزارش ارزی'!$H$8:$H$9818,I34,'ریز گزارش ارزی'!$F$8:$F$9818,J34,'ریز گزارش ارزی'!$G$8:$G$9818,L34) -> 0
B35: € | C35: Project 1 | D35: قرض | E35: راه اندازی | F35: =SUMIFS('ریز گزارش ارزی'!$AC$8:$AC$9818,'ریز گزارش ارزی'!$AC$8:$AC$9818,">0",'ریز گزارش ارزی'!$AF$8:$AF$9818,"4",'ریز گزارش ارزی'!$H$8:$H$9818,B35,'ریز گزارش ارزی'!$F$8:$F$9818,C35,'ریز گزارش ارزی'!$G$8:$G$9818,E35) -> 0 | G35: =SUMIFS('ریز گزارش ارزی'!$AD$8:$AD$9818,'ریز گزارش ارزی'!$AD$8:$AD$9818,">0",'ریز گزارش ارزی'!$AF$8:$AF$9818,"4",'ریز گزارش ارزی'!$H$8:$H$9818,B35,'ریز گزارش ارزی'!$F$8:$F$9818,C35,'ریز گزارش ارزی'!$G$8:$G$9818,E35) -> 0 | I35: € | J35: Project 2 | K35: دریافتی از کارفرما | L35: راه اندازی | M35: =SUMIFS('ریز گزارش ارزی'!$L$8:$L$9818,'ریز گزارش ارزی'!$L$8:$L$9818,">0",'ریز گزارش ارزی'!$H$8:$H$9818,I35,'ریز گزارش ارزی'!$F$8:$F$9818,J35,'ریز گزارش ارزی'!$G$8:$G$9818,L35) -> 0
B36: € | C36: Project 1 | D36: قرض | E36: مکانیکال | F36: =SUMIFS('ریز گزارش ارزی'!$AC$8:$AC$9818,'ریز گزارش ارزی'!$AC$8:$AC$9818,">0",'ریز گزارش ارزی'!$AF$8:$AF$9818,"4",'ریز گزارش ارزی'!$H$8:$H$9818,B36,'ریز گزارش ارزی'!$F$8:$F$9818,C36,'ریز گزارش ارزی'!$G$8:$G$9818,E36) -> 0 | G36: =SUMIFS('ریز گزارش ارزی'!$AD$8:$AD$9818,'ریز گزارش ارزی'!$AD$8:$AD$9818,">0",'ریز گزارش ارزی'!$AF$8:$AF$9818,"4",'ریز گزارش ارزی'!$H$8:$H$9818,B36,'ریز گزارش ارزی'!$F$8:$F$9818,C36,'ریز گزارش ارزی'!$G$8:$G$9818,E36) -> 0 | I36: € | J36: Project 2 | K36: دریافتی از کارفرما | L36: مکانیکال | M36: =SUMIFS('ریز گزارش ارزی'!$L$8:$L$9818,'ریز گزارش ارزی'!$L$8:$L$9818,">0",'ریز گزارش ارزی'!$H$8:$H$9818,I36,'ریز گزارش ارزی'!$F$8:$F$9818,J36,'ریز گزارش ارزی'!$G$8:$G$9818,L36) -> 0
B37: € | C37: Project 1 | D37: قرض | E37: مهندسی | F37: =SUMIFS('ریز گزارش ارزی'!$AC$8:$AC$9818,'ریز گزارش ارزی'!$AC$8:$AC$9818,">0",'ریز گزارش ارزی'!$AF$8:$AF$9818,"4",'ریز گزارش ارزی'!$H$8:$H$9818,B37,'ریز گزارش ارزی'!$F$8:$F$9818,C37,'ریز گزارش ارزی'!$G$8:$G$9818,E37) -> 0 | G37: =SUMIFS('ریز گزارش ارزی'!$AD$8:$AD$9818,'ریز گزارش ارزی'!$AD$8:$AD$9818,">0",'ریز گزارش ارزی'!$AF$8:$AF$9818,"4",'ریز گزارش ارزی'!$H$8:$H$9818,B37,'ریز گزارش ارزی'!$F$8:$F$9818,C37,'ریز گزارش ارزی'!$G$8:$G$9818,E37) -> 0 | I37: € | J37: Project 2 | K37: دریافتی از کارفرما | L37: مهندسی | M37: =SUMIFS('ریز گزارش ارزی'!$L$8:$L$9818,'ریز گزارش ارزی'!$L$8:$L$9818,">0",'ریز گزارش ارزی'!$H$8:$H$9818,I37,'ریز گزارش ارزی'!$F$8:$F$9818,J37,'ریز گزارش ارزی'!$G$8:$G$9818,L37) -> 0
